Workbook

Sheet T LIGHT HOLDER 
A1: Week_start | B1: 22423 REGENCY CAKESTAND 3 TI | C1: 85123A WHITE HANGING HEART T- | D1: 85099B JUMBO BAG RED RETROSPO | E1: 47566 PARTY BUNTING | F1: 84879 ASSORTED COLOUR BIRD O | G1: 22086 PAPER CHAIN KIT 50'S C | H1: 79321 CHILLI LIGHTS | I1: 22197 SMALL POPCORN HOLDER | J1: 22386 JUMBO BAG PINK POLKADO | K1: 20725 LUNCH BAG RED RETROSPO | L1: MA3_FORECAST | M1: ERROR | N1: ABS ERROR | O1: ES_0.1 | P1: ES_0.3 | Q1: ES_0.5 | R1: ALPHA | S1: 0.1 | V1: ABSERR_0.1 | W1: ABSERR_0.3 | X1: ABSERR_0.5
A2: 40154 | B2: 0 | C2: 3166 | D2: 1233 | E2: 19 | F2: 1213 | G2: 663 | H2: 175 | I2: 153 | J2: 0 | K2: 324 | O2: =(C2) -> 3166 | P2: =(C2) -> 3166 | Q2: =(C2) -> 3166 | S2: 0.3
A3: 40161 | B3: 0 | C3: 1294 | D3: 1304 | E3: 52 | F3: 1324 | G3: 572 | H3: 173 | I3: 644 | J3: 0 | K3: 236 | O3: =($S$1*C2+(1-$S$1)*O2) -> 3166 | P3: =($S$2*C2+(1-$S$2)*P2) -> 3166 | Q3: =($S$3*C2+(1-$S$3)*Q2) -> 3166 | S3: 0.5 | V3: =ABS(C3-O3) -> 1872 | W3: =ABS(C3-P3) -> 1872 | X3: =ABS(C3-Q3) -> 1872
A4: 40168 | B4: 0 | C4: 128 | D4: 36 | E4: 1 | F4: 82 | G4: 69 | H4: 19 | I4: 2 | J4: 0 | K4: 111 | O4: =($S$1*C3+(1-$S$1)*O3) -> 2978.8 | P4: =($S$2*C3+(1-$S$2)*P3) -> 2604.4 | Q4: =($S$3*C3+(1-$S$3)*Q3) -> 2230 | V4: =ABS(C4-O4) -> 2850.8 | W4: =ABS(C4-P4) -> 2476.4 | X4: =ABS(C4-Q4) -> 2102
A5: 40175 | B5: 0 | C5: 0 | D5: 0 | E5: 0 | F5: 0 | G5: 0 | H5: 0 | I5: 0 | J5: 0 | K5: 0 | L5: =AVERAGE(C2:C4) -> 1529.3333 | M5: =(C5-L5) -> -1529.3333 | N5: =ABS(M5) -> 1529.3333 | O5: =($S$1*C4+(1-$S$1)*O4) -> 2693.72 | P5: =($S$2*C4+(1-$S$2)*P4) -> 1861.48 | Q5: =($S$3*C4+(1-$S$3)*Q4) -> 1179 | V5: =ABS(C5-O5) -> 2693.72 | W5: =ABS(C5-P5) -> 1861.48 | X5: =ABS(C5-Q5) -> 1179
A6: 40182 | B6: 0 | C6: 1773 | D6: 1152 | E6: 47 | F6: 168 | G6: 0 | H6: 17 | I6: 21 | J6: 0 | K6: 324 | L6: =AVERAGE(C3:C5) -> 474 | M6: =(C6-L6) -> 1299 | N6: =ABS(M6) -> 1299 | O6: =($S$1*C5+(1-$S$1)*O5) -> 2424.348 | P6: =($S$2*C5+(1-$S$2)*P5) -> 1303.036 | Q6: =($S$3*C5+(1-$S$3)*Q5) -> 589.5 | V6: =ABS(C6-O6) -> 651.348 | W6: =ABS(C6-P6) -> 469.964 | X6: =ABS(C6-Q6) -> 1183.5
A7: 40189 | B7: 0 | C7: 920 | D7: 928 | E7: 64 | F7: 233 | G7: 20 | H7: 23 | I7: 72 | J7: 0 | K7: 190 | L7: =AVERAGE(C4:C6) -> 633.66667 | M7: =(C7-L7) -> 286.33333 | N7: =ABS(M7) -> 286.33333 | O7: =($S$1*C6+(1-$S$1)*O6) -> 2359.2132 | P7: =($S$2*C6+(1-$S$2)*P6) -> 1444.0252 | Q7: =($S$3*C6+(1-$S$3)*Q6) -> 1181.25 | V7: =ABS(C7-O7) -> 1439.2132 | W7: =ABS(C7-P7) -> 524.0252 | X7: =ABS(C7-Q7) -> 261.25
A8: 40196 | B8: 0 | C8: 1404 | D8: 627 | E8: 49 | F8: 897 | G8: 3 | H8: 0 | I8: 23 | J8: 0 | K8: 479 | L8: =AVERAGE(C5:C7) -> 897.66667 | M8: =(C8-L8) -> 506.33333 | N8: =ABS(M8) -> 506.33333 | O8: =($S$1*C7+(1-$S$1)*O7) -> 2215.2919 | P8: =($S$2*C7+(1-$S$2)*P7) -> 1286.8176 | Q8: =($S$3*C7+(1-$S$3)*Q7) -> 1050.625 | V8: =ABS(C8-O8) -> 811.29188 | W8: =ABS(C8-P8) -> 117.18236 | X8: =ABS(C8-Q8) -> 353.375
A9: 40203 | B9: 0 | C9: 1382 | D9: 864 | E9: 186 | F9: 211 | G9: 0 | H9: 0 | I9: 621 | J9: 114 | K9: 504 | L9: =AVERAGE(C6:C8) -> 1365.6667 | M9: =(C9-L9) -> 16.333333 | N9: =ABS(M9) -> 16.333333 | O9: =($S$1*C8+(1-$S$1)*O8) -> 2134.1627 | P9: =($S$2*C8+(1-$S$2)*P8) -> 1321.9723 | Q9: =($S$3*C8+(1-$S$3)*Q8) -> 1227.3125 | V9: =ABS(C9-O9) -> 752.16269 | W9: =ABS(C9-P9) -> 60.027652 | X9: =ABS(C9-Q9) -> 154.6875
A10: 40210 | B10: 0 | C10: 727 | D10: 488 | E10: 53 | F10: 274 | G10: 0 | H10: 24 | I10: 81 | J10: 338 | K10: 326 | L10: =AVERAGE(C7:C9) -> 1235.3333 | M10: =(C10-L10) -> -508.33333 | N10: =ABS(M10) -> 508.33333 | O10: =($S$1*C9+(1-$S$1)*O9) -> 2058.9464 | P10: =($S$2*C9+(1-$S$2)*P9) -> 1339.9806 | Q10: =($S$3*C9+(1-$S$3)*Q9) -> 1304.6562 | V10: =ABS(C10-O10) -> 1331.9464 | W10: =ABS(C10-P10) -> 612.98064 | X10: =ABS(C10-Q10) -> 577.65625
A11: 40217 | B11: 0 | C11: 580 | D11: 547 | E11: 51 | F11: 512 | G11: 0 | H11: 0 | I11: 68 | J11: 314 | K11: 213 | L11: =AVERAGE(C8:C10) -> 1171 | M11: =(C11-L11) -> -591 | N11: =ABS(M11) -> 591 | O11: =($S$1*C10+(1-$S$1)*O10) -> 1925.7518 | P11: =($S$2*C10+(1-$S$2)*P10) -> 1156.0865 | Q11: =($S$3*C10+(1-$S$3)*Q10) -> 1015.8281 | V11: =ABS(C11-O11) -> 1345.7518 | W11: =ABS(C11-P11) -> 576.08645 | X11: =ABS(C11-Q11) -> 435.82812
A12: 40224 | B12: 0 | C12: 669 | D12: 1014 | E12: 159 | F12: 587 | G12: 0 | H12: 1 | I12: 19 | J12: 720 | K12: 442 | L12: =AVERAGE(C9:C11) -> 896.33333 | M12: =(C12-L12) -> -227.33333 | N12: =ABS(M12) -> 227.33333 | O12: =($S$1*C11+(1-$S$1)*O11) -> 1791.1766 | P12: =($S$2*C11+(1-$S$2)*P11) -> 983.26052 | Q12: =($S$3*C11+(1-$S$3)*Q11) -> 797.91406 | V12: =ABS(C12-O12) -> 1122.1766 | W12: =ABS(C12-P12) -> 314.26052 | X12: =ABS(C12-Q12) -> 128.91406
A13: 40231 | B13: 0 | C13: 929 | D13: 613 | E13: 79 | F13: 294 | G13: 0 | H13: 0 | I13: 1407 | J13: 551 | K13: 272 | L13: =AVERAGE(C10:C12) -> 658.66667 | M13: =(C13-L13) -> 270.33333 | N13: =ABS(M13) -> 270.33333 | O13: =($S$1*C12+(1-$S$1)*O12) -> 1678.9589 | P13: =($S$2*C12+(1-$S$2)*P12) -> 888.98236 | Q13: =($S$3*C12+(1-$S$3)*Q12) -> 733.45703 | V13: =ABS(C13-O13) -> 749.95894 | W13: =ABS(C13-P13) -> 40.017639 | X13: =ABS(C13-Q13) -> 195.54297
A14: 40238 | B14: 0 | C14: 842 | D14: 754 | E14: 78 | F14: 735 | G14: 3 | H14: 2 | I14: 133 | J14: 306 | K14: 409 | L14: =AVERAGE(C11:C13) -> 726 | M14: =(C14-L14) -> 116 | N14: =ABS(M14) -> 116 | O14: =($S$1*C13+(1-$S$1)*O13) -> 1603.963 | P14: =($S$2*C13+(1-$S$2)*P13) -> 900.98765 | Q14: =($S$3*C13+(1-$S$3)*Q13) -> 831.22852 | V14: =ABS(C14-O14) -> 761.96305 | W14: =ABS(C14-P14) -> 58.987653 | X14: =ABS(C14-Q14) -> 10.771484
A15: 40245 | B15: 0 | C15: 848 | D15: 800 | E15: 262 | F15: 917 | G15: 0 | H15: 0 | I15: 47 | J15: 405 | K15: 337 | L15: =AVERAGE(C12:C14) -> 813.33333 | M15: =(C15-L15) -> 34.666667 | N15: =ABS(M15) -> 34.666667 | O15: =($S$1*C14+(1-$S$1)*O14) -> 1527.7667 | P15: =($S$2*C14+(1-$S$2)*P14) -> 883.29136 | Q15: =($S$3*C14+(1-$S$3)*Q14) -> 836.61426 | V15: =ABS(C15-O15) -> 679.76674 | W15: =ABS(C15-P15) -> 35.291357 | X15: =ABS(C15-Q15) -> 11.385742
A16: 40252 | B16: 194 | C16: 1496 | D16: 555 | E16: 224 | F16: 551 | G16: 12 | H16: 0 | I16: 826 | J16: 179 | K16: 375 | L16: =AVERAGE(C13:C15) -> 873 | M16: =(C16-L16) -> 623 | N16: =ABS(M16) -> 623 | O16: =($S$1*C15+(1-$S$1)*O15) -> 1459.7901 | P16: =($S$2*C15+(1-$S$2)*P15) -> 872.70395 | Q16: =($S$3*C15+(1-$S$3)*Q15) -> 842.30713 | V16: =ABS(C16-O16) -> 36.209931 | W16: =ABS(C16-P16) -> 623.29605 | X16: =ABS(C16-Q16) -> 653.69287
... A105: 40875 | B105: 226 | C105: 726 | D105: 1040 | E105: 105 | F105: 953 | G105: 1564 | H105: 314 | I105: 3275 | J105: 436 | K105: 331 | L105: =AVERAGE(C102:C104) -> 931.66667 | M105: =(C105-L105) -> -205.66667 | N105: =ABS(M105) -> 205.66667 | O105: =($S$1*C104+(1-$S$1)*O104) -> 713.99021 | P105: =($S$2*C104+(1-$S$2)*P104) -> 909.21415 | Q105: =($S$3*C104+(1-$S$3)*Q104) -> 983.26206 | V105: =ABS(C105-O105) -> 12.009791 | W105: =ABS(C105-P105) -> 183.21415 | X105: =ABS(C105-Q105) -> 257.26206
T106: MAD _M3 | U106: =AVERAGE(N94:N105) -> 322.88889
T107: MAD _ES_0.1 | U107: =AVERAGE(V94:V105) -> 292.34878
T108: MAD _ES_0.3 | U108: =AVERAGE(W94:W105) -> 310.91623
T109: MAD _ES_0.5 | U109: =AVERAGE(X94:X105) -> 360.64191
V111: AVERAGE | W111: STD DEV
V112: =AVERAGE(C2:C105) -> 850.56731 | W112: =STDEV(C2:C105) -> 496.45232

Sheet JUMBO BAG PINK
A1: Week_start | B1: 22423 REGENCY CAKESTAND 3 TI | C1: 85123A WHITE HANGING HEART T- | D1: 85099B JUMBO BAG RED RETROSPO | E1: 47566 PARTY BUNTING | F1: 84879 ASSORTED COLOUR BIRD O | G1: 22086 PAPER CHAIN KIT 50'S C | H1: 79321 CHILLI LIGHTS | I1: 22197 SMALL POPCORN HOLDER | J1: 22386 JUMBO BAG PINK POLKADO | K1: 20725 LUNCH BAG RED RETROSPO | L1: MA3_FORECAST | M1: ERROR | N1: ABS ERROR | O1: ES_0.1 | P1: ES_0.3 | Q1: ES_0.5 | R1: ALPHA | S1: 0.1 | V1: ABSERR_0.1 | W1: ABSERR_0.3 | X1: ABSERR_0.5
A2: 40154 | B2: 0 | C2: 0 | D2: 1233 | E2: 19 | F2: 1213 | G2: 663 | H2: 175 | I2: 153 | J2: 0 | K2: 324 | O2: =(C2) -> 0 | P2: =(C2) -> 0 | Q2: =(C2) -> 0 | S2: 0.3
A3: 40161 | B3: 0 | C3: 0 | D3: 1304 | E3: 52 | F3: 1324 | G3: 572 | H3: 173 | I3: 644 | J3: 0 | K3: 236 | O3: =($S$1*C2+(1-$S$1)*O2) -> 0 | P3: =($S$2*C2+(1-$S$2)*P2) -> 0 | Q3: =($S$3*C2+(1-$S$3)*Q2) -> 0 | S3: 0.5 | V3: =ABS(C3-O3) -> 0 | W3: =ABS(C3-P3) -> 0 | X3: =ABS(C3-Q3) -> 0
A4: 40168 | B4: 0 | C4: 0 | D4: 36 | E4: 1 | F4: 82 | G4: 69 | H4: 19 | I4: 2 | J4: 0 | K4: 111 | O4: =($S$1*C3+(1-$S$1)*O3) -> 0 | P4: =($S$2*C3+(1-$S$2)*P3) -> 0 | Q4: =($S$3*C3+(1-$S$3)*Q3) -> 0 | V4: =ABS(C4-O4) -> 0 | W4: =ABS(C4-P4) -> 0 | X4: =ABS(C4-Q4) -> 0
A5: 40175 | B5: 0 | C5: 0 | D5: 0 | E5: 0 | F5: 0 | G5: 0 | H5: 0 | I5: 0 | J5: 0 | K5: 0 | L5: =AVERAGE(C2:C4) -> 0 | M5: =(C5-L5) -> 0 | N5: =ABS(M5) -> 0 | O5: =($S$1*C4+(1-$S$1)*O4) -> 0 | P5: =($S$2*C4+(1-$S$2)*P4) -> 0 | Q5: =($S$3*C4+(1-$S$3)*Q4) -> 0 | V5: =ABS(C5-O5) -> 0 | W5: =ABS(C5-P5) -> 0 | X5: =ABS(C5-Q5) -> 0
A6: 40182 | B6: 0 | C6: 0 | D6: 1152 | E6: 47 | F6: 168 | G6: 0 | H6: 17 | I6: 21 | J6: 0 | K6: 324 | L6: =AVERAGE(C3:C5) -> 0 | M6: =(C6-L6) -> 0 | N6: =ABS(M6) -> 0 | O6: =($S$1*C5+(1-$S$1)*O5) -> 0 | P6: =($S$2*C5+(1-$S$2)*P5) -> 0 | Q6: =($S$3*C5+(1-$S$3)*Q5) -> 0 | V6: =ABS(C6-O6) -> 0 | W6: =ABS(C6-P6) -> 0 | X6: =ABS(C6-Q6) -> 0
A7: 40189 | B7: 0 | C7: 0 | D7: 928 | E7: 64 | F7: 233 | G7: 20 | H7: 23 | I7: 72 | J7: 0 | K7: 190 | L7: =AVERAGE(C4:C6) -> 0 | M7: =(C7-L7) -> 0 | N7: =ABS(M7) -> 0 | O7: =($S$1*C6+(1-$S$1)*O6) -> 0 | P7: =($S$2*C6+(1-$S$2)*P6) -> 0 | Q7: =($S$3*C6+(1-$S$3)*Q6) -> 0 | V7: =ABS(C7-O7) -> 0 | W7: =ABS(C7-P7) -> 0 | X7: =ABS(C7-Q7) -> 0
A8: 40196 | B8: 0 | C8: 0 | D8: 627 | E8: 49 | F8: 897 | G8: 3 | H8: 0 | I8: 23 | J8: 0 | K8: 479 | L8: =AVERAGE(C5:C7) -> 0 | M8: =(C8-L8) -> 0 | N8: =ABS(M8) -> 0 | O8: =($S$1*C7+(1-$S$1)*O7) -> 0 | P8: =($S$2*C7+(1-$S$2)*P7) -> 0 | Q8: =($S$3*C7+(1-$S$3)*Q7) -> 0 | V8: =ABS(C8-O8) -> 0 | W8: =ABS(C8-P8) -> 0 | X8: =ABS(C8-Q8) -> 0
A9: 40203 | B9: 0 | C9: 114 | D9: 864 | E9: 186 | F9: 211 | G9: 0 | H9: 0 | I9: 621 | J9: 114 | K9: 504 | L9: =AVERAGE(C6:C8) -> 0 | M9: =(C9-L9) -> 114 | N9: =ABS(M9) -> 114 | O9: =($S$1*C8+(1-$S$1)*O8) -> 0 | P9: =($S$2*C8+(1-$S$2)*P8) -> 0 | Q9: =($S$3*C8+(1-$S$3)*Q8) -> 0 | V9: =ABS(C9-O9) -> 114 | W9: =ABS(C9-P9) -> 114 | X9: =ABS(C9-Q9) -> 114
A10: 40210 | B10: 0 | C10: 338 | D10: 488 | E10: 53 | F10: 274 | G10: 0 | H10: 24 | I10: 81 | J10: 338 | K10: 326 | L10: =AVERAGE(C7:C9) -> 38 | M10: =(C10-L10) -> 300 | N10: =ABS(M10) -> 300 | O10: =($S$1*C9+(1-$S$1)*O9) -> 11.4 | P10: =($S$2*C9+(1-$S$2)*P9) -> 34.2 | Q10: =($S$3*C9+(1-$S$3)*Q9) -> 57 | V10: =ABS(C10-O10) -> 326.6 | W10: =ABS(C10-P10) -> 303.8 | X10: =ABS(C10-Q10) -> 281
A11: 40217 | B11: 0 | C11: 314 | D11: 547 | E11: 51 | F11: 512 | G11: 0 | H11: 0 | I11: 68 | J11: 314 | K11: 213 | L11: =AVERAGE(C8:C10) -> 150.66667 | M11: =(C11-L11) -> 163.33333 | N11: =ABS(M11) -> 163.33333 | O11: =($S$1*C10+(1-$S$1)*O10) -> 44.06 | P11: =($S$2*C10+(1-$S$2)*P10) -> 125.34 | Q11: =($S$3*C10+(1-$S$3)*Q10) -> 197.5 | V11: =ABS(C11-O11) -> 269.94 | W11: =ABS(C11-P11) -> 188.66 | X11: =ABS(C11-Q11) -> 116.5
A12: 40224 | B12: 0 | C12: 720 | D12: 1014 | E12: 159 | F12: 587 | G12: 0 | H12: 1 | I12: 19 | J12: 720 | K12: 442 | L12: =AVERAGE(C9:C11) -> 255.33333 | M12: =(C12-L12) -> 464.66667 | N12: =ABS(M12) -> 464.66667 | O12: =($S$1*C11+(1-$S$1)*O11) -> 71.054 | P12: =($S$2*C11+(1-$S$2)*P11) -> 181.938 | Q12: =($S$3*C11+(1-$S$3)*Q11) -> 255.75 | V12: =ABS(C12-O12) -> 648.946 | W12: =ABS(C12-P12) -> 538.062 | X12: =ABS(C12-Q12) -> 464.25
A13: 40231 | B13: 0 | C13: 551 | D13: 613 | E13: 79 | F13: 294 | G13: 0 | H13: 0 | I13: 1407 | J13: 551 | K13: 272 | L13: =AVERAGE(C10:C12) -> 457.33333 | M13: =(C13-L13) -> 93.666667 | N13: =ABS(M13) -> 93.666667 | O13: =($S$1*C12+(1-$S$1)*O12) -> 135.9486 | P13: =($S$2*C12+(1-$S$2)*P12) -> 343.3566 | Q13: =($S$3*C12+(1-$S$3)*Q12) -> 487.875 | V13: =ABS(C13-O13) -> 415.0514 | W13: =ABS(C13-P13) -> 207.6434 | X13: =ABS(C13-Q13) -> 63.125
A14: 40238 | B14: 0 | C14: 306 | D14: 754 | E14: 78 | F14: 735 | G14: 3 | H14: 2 | I14: 133 | J14: 306 | K14: 409 | L14: =AVERAGE(C11:C13) -> 528.33333 | M14: =(C14-L14) -> -222.33333 | N14: =ABS(M14) -> 222.33333 | O14: =($S$1*C13+(1-$S$1)*O13) -> 177.45374 | P14: =($S$2*C13+(1-$S$2)*P13) -> 405.64962 | Q14: =($S$3*C13+(1-$S$3)*Q13) -> 519.4375 | V14: =ABS(C14-O14) -> 128.54626 | W14: =ABS(C14-P14) -> 99.64962 | X14: =ABS(C14-Q14) -> 213.4375
A15: 40245 | B15: 0 | C15: 405 | D15: 800 | E15: 262 | F15: 917 | G15: 0 | H15: 0 | I15: 47 | J15: 405 | K15: 337 | L15: =AVERAGE(C12:C14) -> 525.66667 | M15: =(C15-L15) -> -120.66667 | N15: =ABS(M15) -> 120.66667 | O15: =($S$1*C14+(1-$S$1)*O14) -> 190.30837 | P15: =($S$2*C14+(1-$S$2)*P14) -> 375.75473 | Q15: =($S$3*C14+(1-$S$3)*Q14) -> 412.71875 | V15: =ABS(C15-O15) -> 214.69163 | W15: =ABS(C15-P15) -> 29.245266 | X15: =ABS(C15-Q15) -> 7.71875
A16: 40252 | B16: 194 | C16: 179 | D16: 555 | E16: 224 | F16: 551 | G16: 12 | H16: 0 | I16: 826 | J16: 179 | K16: 375 | L16: =AVERAGE(C13:C15) -> 420.66667 | M16: =(C16-L16) -> -241.66667 | N16: =ABS(M16) -> 241.66667 | O16: =($S$1*C15+(1-$S$1)*O15) -> 211.77753 | P16: =($S$2*C15+(1-$S$2)*P15) -> 384.52831 | Q16: =($S$3*C15+(1-$S$3)*Q15) -> 408.85938 | V16: =ABS(C16-O16) -> 32.777529 | W16: =ABS(C16-P16) -> 205.52831 | X16: =ABS(C16-Q16) -> 229.85938
... A105: 40875 | B105: 226 | C105: 436 | D105: 1040 | E105: 105 | F105: 953 | G105: 1564 | H105: 314 | I105: 3275 | J105: 436 | K105: 331 | L105: =AVERAGE(C102:C104) -> 397 | M105: =(C105-L105) -> 39 | N105: =ABS(M105) -> 39 | O105: =($S$1*C104+(1-$S$1)*O104) -> 496.35066 | P105: =($S$2*C104+(1-$S$2)*P104) -> 426.46233 | Q105: =($S$3*C104+(1-$S$3)*Q104) -> 364.75076 | V105: =ABS(C105-O105) -> 60.350662 | W105: =ABS(C105-P105) -> 9.5376724 | X105: =ABS(C105-Q105) -> 71.249245
T106: MAD _M3 | U106: =AVERAGE(N94:N105) -> 265.33333
T107: MAD _ES_0.1 | U107: =AVERAGE(V94:V105) -> 262.64284
T108: MAD _ES_0.3 | U108: =AVERAGE(W94:W105) -> 271.50823
T109: MAD _ES_0.5 | U109: =AVERAGE(X94:X105) -> 287.00668
V111: AVERAGE | W111: STD DEV
V112: =AVERAGE(C2:C105) -> 374.125 | W112: =STDEV(C2:C105) -> 254.29952

Sheet LUNCH BAG RED
A1: Week_start | B1: 22423 REGENCY CAKESTAND 3 TI | C1: 85123A WHITE HANGING HEART T- | D1: 85099B JUMBO BAG RED RETROSPO | E1: 47566 PARTY BUNTING | F1: 84879 ASSORTED COLOUR BIRD O | G1: 22086 PAPER CHAIN KIT 50'S C | H1: 79321 CHILLI LIGHTS | I1: 22197 SMALL POPCORN HOLDER | J1: 22386 JUMBO BAG PINK POLKADO | K1: 20725 LUNCH BAG RED RETROSPO | L1: MA3_FORECAST | M1: ERROR | N1: ABS ERROR | O1: ES_0.1 | P1: ES_0.3 | Q1: ES_0.5 | R1: ALPHA | S1: 0.1 | V1: ABSERR_0.1 | W1: ABSERR_0.3 | X1: ABSERR_0.5
A2: 40154 | B2: 0 | C2: 324 | D2: 1233 | E2: 19 | F2: 1213 | G2: 663 | H2: 175 | I2: 153 | J2: 0 | K2: 324 | O2: =(C2) -> 324 | P2: =(C2) -> 324 | Q2: =(C2) -> 324 | S2: 0.3
A3: 40161 | B3: 0 | C3: 236 | D3: 1304 | E3: 52 | F3: 1324 | G3: 572 | H3: 173 | I3: 644 | J3: 0 | K3: 236 | O3: =($S$1*C2+(1-$S$1)*O2) -> 324 | P3: =($S$2*C2+(1-$S$2)*P2) -> 324 | Q3: =($S$3*C2+(1-$S$3)*Q2) -> 324 | S3: 0.5 | V3: =ABS(C3-O3) -> 88 | W3: =ABS(C3-P3) -> 88 | X3: =ABS(C3-Q3) -> 88
A4: 40168 | B4: 0 | C4: 111 | D4: 36 | E4: 1 | F4: 82 | G4: 69 | H4: 19 | I4: 2 | J4: 0 | K4: 111 | O4: =($S$1*C3+(1-$S$1)*O3) -> 315.2 | P4: =($S$2*C3+(1-$S$2)*P3) -> 297.6 | Q4: =($S$3*C3+(1-$S$3)*Q3) -> 280 | V4: =ABS(C4-O4) -> 204.2 | W4: =ABS(C4-P4) -> 186.6 | X4: =ABS(C4-Q4) -> 169
A5: 40175 | B5: 0 | C5: 0 | D5: 0 | E5: 0 | F5: 0 | G5: 0 | H5: 0 | I5: 0 | J5: 0 | K5: 0 | L5: =AVERAGE(C2:C4) -> 223.66667 | M5: =(C5-L5) -> -223.66667 | N5: =ABS(M5) -> 223.66667 | O5: =($S$1*C4+(1-$S$1)*O4) -> 294.78 | P5: =($S$2*C4+(1-$S$2)*P4) -> 241.62 | Q5: =($S$3*C4+(1-$S$3)*Q4) -> 195.5 | V5: =ABS(C5-O5) -> 294.78 | W5: =ABS(C5-P5) -> 241.62 | X5: =ABS(C5-Q5) -> 195.5
A6: 40182 | B6: 0 | C6: 324 | D6: 1152 | E6: 47 | F6: 168 | G6: 0 | H6: 17 | I6: 21 | J6: 0 | K6: 324 | L6: =AVERAGE(C3:C5) -> 115.66667 | M6: =(C6-L6) -> 208.33333 | N6: =ABS(M6) -> 208.33333 | O6: =($S$1*C5+(1-$S$1)*O5) -> 265.302 | P6: =($S$2*C5+(1-$S$2)*P5) -> 169.134 | Q6: =($S$3*C5+(1-$S$3)*Q5) -> 97.75 | V6: =ABS(C6-O6) -> 58.698 | W6: =ABS(C6-P6) -> 154.866 | X6: =ABS(C6-Q6) -> 226.25
A7: 40189 | B7: 0 | C7: 190 | D7: 928 | E7: 64 | F7: 233 | G7: 20 | H7: 23 | I7: 72 | J7: 0 | K7: 190 | L7: =AVERAGE(C4:C6) -> 145 | M7: =(C7-L7) -> 45 | N7: =ABS(M7) -> 45 | O7: =($S$1*C6+(1-$S$1)*O6) -> 271.1718 | P7: =($S$2*C6+(1-$S$2)*P6) -> 215.5938 | Q7: =($S$3*C6+(1-$S$3)*Q6) -> 210.875 | V7: =ABS(C7-O7) -> 81.1718 | W7: =ABS(C7-P7) -> 25.5938 | X7: =ABS(C7-Q7) -> 20.875
A8: 40196 | B8: 0 | C8: 479 | D8: 627 | E8: 49 | F8: 897 | G8: 3 | H8: 0 | I8: 23 | J8: 0 | K8: 479 | L8: =AVERAGE(C5:C7) -> 171.33333 | M8: =(C8-L8) -> 307.66667 | N8: =ABS(M8) -> 307.66667 | O8: =($S$1*C7+(1-$S$1)*O7) -> 263.05462 | P8: =($S$2*C7+(1-$S$2)*P7) -> 207.91566 | Q8: =($S$3*C7+(1-$S$3)*Q7) -> 200.4375 | V8: =ABS(C8-O8) -> 215.94538 | W8: =ABS(C8-P8) -> 271.08434 | X8: =ABS(C8-Q8) -> 278.5625
A9: 40203 | B9: 0 | C9: 504 | D9: 864 | E9: 186 | F9: 211 | G9: 0 | H9: 0 | I9: 621 | J9: 114 | K9: 504 | L9: =AVERAGE(C6:C8) -> 331 | M9: =(C9-L9) -> 173 | N9: =ABS(M9) -> 173 | O9: =($S$1*C8+(1-$S$1)*O8) -> 284.64916 | P9: =($S$2*C8+(1-$S$2)*P8) -> 289.24096 | Q9: =($S$3*C8+(1-$S$3)*Q8) -> 339.71875 | V9: =ABS(C9-O9) -> 219.35084 | W9: =ABS(C9-P9) -> 214.75904 | X9: =ABS(C9-Q9) -> 164.28125
A10: 40210 | B10: 0 | C10: 326 | D10: 488 | E10: 53 | F10: 274 | G10: 0 | H10: 24 | I10: 81 | J10: 338 | K10: 326 | L10: =AVERAGE(C7:C9) -> 391 | M10: =(C10-L10) -> -65 | N10: =ABS(M10) -> 65 | O10: =($S$1*C9+(1-$S$1)*O9) -> 306.58424 | P10: =($S$2*C9+(1-$S$2)*P9) -> 353.66867 | Q10: =($S$3*C9+(1-$S$3)*Q9) -> 421.85938 | V10: =ABS(C10-O10) -> 19.415758 | W10: =ABS(C10-P10) -> 27.668673 | X10: =ABS(C10-Q10) -> 95.859375
A11: 40217 | B11: 0 | C11: 213 | D11: 547 | E11: 51 | F11: 512 | G11: 0 | H11: 0 | I11: 68 | J11: 314 | K11: 213 | L11: =AVERAGE(C8:C10) -> 436.33333 | M11: =(C11-L11) -> -223.33333 | N11: =ABS(M11) -> 223.33333 | O11: =($S$1*C10+(1-$S$1)*O10) -> 308.52582 | P11: =($S$2*C10+(1-$S$2)*P10) -> 345.36807 | Q11: =($S$3*C10+(1-$S$3)*Q10) -> 373.92969 | V11: =ABS(C11-O11) -> 95.525818 | W11: =ABS(C11-P11) -> 132.36807 | X11: =ABS(C11-Q11) -> 160.92969
A12: 40224 | B12: 0 | C12: 442 | D12: 1014 | E12: 159 | F12: 587 | G12: 0 | H12: 1 | I12: 19 | J12: 720 | K12: 442 | L12: =AVERAGE(C9:C11) -> 347.66667 | M12: =(C12-L12) -> 94.333333 | N12: =ABS(M12) -> 94.333333 | O12: =($S$1*C11+(1-$S$1)*O11) -> 298.97324 | P12: =($S$2*C11+(1-$S$2)*P11) -> 305.65765 | Q12: =($S$3*C11+(1-$S$3)*Q11) -> 293.46484 | V12: =ABS(C12-O12) -> 143.02676 | W12: =ABS(C12-P12) -> 136.34235 | X12: =ABS(C12-Q12) -> 148.53516
A13: 40231 | B13: 0 | C13: 272 | D13: 613 | E13: 79 | F13: 294 | G13: 0 | H13: 0 | I13: 1407 | J13: 551 | K13: 272 | L13: =AVERAGE(C10:C12) -> 327 | M13: =(C13-L13) -> -55 | N13: =ABS(M13) -> 55 | O13: =($S$1*C12+(1-$S$1)*O12) -> 313.27591 | P13: =($S$2*C12+(1-$S$2)*P12) -> 346.56036 | Q13: =($S$3*C12+(1-$S$3)*Q12) -> 367.73242 | V13: =ABS(C13-O13) -> 41.275913 | W13: =ABS(C13-P13) -> 74.560355 | X13: =ABS(C13-Q13) -> 95.732422
A14: 40238 | B14: 0 | C14: 409 | D14: 754 | E14: 78 | F14: 735 | G14: 3 | H14: 2 | I14: 133 | J14: 306 | K14: 409 | L14: =AVERAGE(C11:C13) -> 309 | M14: =(C14-L14) -> 100 | N14: =ABS(M14) -> 100 | O14: =($S$1*C13+(1-$S$1)*O13) -> 309.14832 | P14: =($S$2*C13+(1-$S$2)*P13) -> 324.19225 | Q14: =($S$3*C13+(1-$S$3)*Q13) -> 319.86621 | V14: =ABS(C14-O14) -> 99.851679 | W14: =ABS(C14-P14) -> 84.807752 | X14: =ABS(C14-Q14) -> 89.133789
A15: 40245 | B15: 0 | C15: 337 | D15: 800 | E15: 262 | F15: 917 | G15: 0 | H15: 0 | I15: 47 | J15: 405 | K15: 337 | L15: =AVERAGE(C12:C14) -> 374.33333 | M15: =(C15-L15) -> -37.333333 | N15: =ABS(M15) -> 37.333333 | O15: =($S$1*C14+(1-$S$1)*O14) -> 319.13349 | P15: =($S$2*C14+(1-$S$2)*P14) -> 349.63457 | Q15: =($S$3*C14+(1-$S$3)*Q14) -> 364.43311 | V15: =ABS(C15-O15) -> 17.866511 | W15: =ABS(C15-P15) -> 12.634574 | X15: =ABS(C15-Q15) -> 27.433105
A16: 40252 | B16: 194 | C16: 375 | D16: 555 | E16: 224 | F16: 551 | G16: 12 | H16: 0 | I16: 826 | J16: 179 | K16: 375 | L16: =AVERAGE(C13:C15) -> 339.33333 | M16: =(C16-L16) -> 35.666667 | N16: =ABS(M16) -> 35.666667 | O16: =($S$1*C15+(1-$S$1)*O15) -> 320.92014 | P16: =($S$2*C15+(1-$S$2)*P15) -> 345.8442 | Q16: =($S$3*C15+(1-$S$3)*Q15) -> 350.71655 | V16: =ABS(C16-O16) -> 54.07986 | W16: =ABS(C16-P16) -> 29.155798 | X16: =ABS(C16-Q16) -> 24.283447
... A105: 40875 | B105: 226 | C105: 331 | D105: 1040 | E105: 105 | F105: 953 | G105: 1564 | H105: 314 | I105: 3275 | J105: 436 | K105: 331 | L105: =AVERAGE(C102:C104) -> 494 | M105: =(C105-L105) -> -163 | N105: =ABS(M105) -> 163 | O105: =($S$1*C104+(1-$S$1)*O104) -> 394.38964 | P105: =($S$2*C104+(1-$S$2)*P104) -> 405.96357 | Q105: =($S$3*C104+(1-$S$3)*Q104) -> 404.21419 | V105: =ABS(C105-O105) -> 63.389641 | W105: =ABS(C105-P105) -> 74.963566 | X105: =ABS(C105-Q105) -> 73.214189
T106: MAD _M3 | U106: =AVERAGE(N94:N105) -> 130.08333
T107: MAD _ES_0.1 | U107: =AVERAGE(V94:V105) -> 114.92427
T108: MAD _ES_0.3 | U108: =AVERAGE(W94:W105) -> 120.42201
T109: MAD _ES_0.5 | U109: =AVERAGE(X94:X105) -> 125.1226
V111: AVERAGE | W111: STD DEV
V112: =AVERAGE(C2:C105) -> 378.50962 | W112: =STDEV(C2:C105) -> 175.84702

Sheet POPCORN HOLDER
A1: Week_start | B1: 22423 REGENCY CAKESTAND 3 TI | C1: 85123A WHITE HANGING HEART T- | D1: 85099B JUMBO BAG RED RETROSPO | E1: 47566 PARTY BUNTING | F1: 84879 ASSORTED COLOUR BIRD O | G1: 22086 PAPER CHAIN KIT 50'S C | H1: 79321 CHILLI LIGHTS | I1: 22197 SMALL POPCORN HOLDER | J1: 22386 JUMBO BAG PINK POLKADO | K1: 20725 LUNCH BAG RED RETROSPO | L1: MA3_FORECAST | M1: ERROR | N1: ABS ERROR | O1: ES_0.1 | P1: ES_0.3 | Q1: ES_0.5 | R1: ALPHA | S1: 0.1 | V1: ABSERR_0.1 | W1: ABSERR_0.3 | X1: ABSERR_0.5
A2: 40154 | B2: 0 | C2: 153 | D2: 1233 | E2: 19 | F2: 1213 | G2: 663 | H2: 175 | I2: 153 | J2: 0 | K2: 324 | O2: =(C2) -> 153 | P2: =(C2) -> 153 | Q2: =(C2) -> 153 | S2: 0.3
A3: 40161 | B3: 0 | C3: 644 | D3: 1304 | E3: 52 | F3: 1324 | G3: 572 | H3: 173 | I3: 644 | J3: 0 | K3: 236 | O3: =($S$1*C2+(1-$S$1)*O2) -> 153 | P3: =($S$2*C2+(1-$S$2)*P2) -> 153 | Q3: =($S$3*C2+(1-$S$3)*Q2) -> 153 | S3: 0.5 | V3: =ABS(C3-O3) -> 491 | W3: =ABS(C3-P3) -> 491 | X3: =ABS(C3-Q3) -> 491
A4: 40168 | B4: 0 | C4: 2 | D4: 36 | E4: 1 | F4: 82 | G4: 69 | H4: 19 | I4: 2 | J4: 0 | K4: 111 | O4: =($S$1*C3+(1-$S$1)*O3) -> 202.1 | P4: =($S$2*C3+(1-$S$2)*P3) -> 300.3 | Q4: =($S$3*C3+(1-$S$3)*Q3) -> 398.5 | V4: =ABS(C4-O4) -> 200.1 | W4: =ABS(C4-P4) -> 298.3 | X4: =ABS(C4-Q4) -> 396.5
A5: 40175 | B5: 0 | C5: 0 | D5: 0 | E5: 0 | F5: 0 | G5: 0 | H5: 0 | I5: 0 | J5: 0 | K5: 0 | L5: =AVERAGE(C2:C4) -> 266.33333 | M5: =(C5-L5) -> -266.33333 | N5: =ABS(M5) -> 266.33333 | O5: =($S$1*C4+(1-$S$1)*O4) -> 182.09 | P5: =($S$2*C4+(1-$S$2)*P4) -> 210.81 | Q5: =($S$3*C4+(1-$S$3)*Q4) -> 200.25 | V5: =ABS(C5-O5) -> 182.09 | W5: =ABS(C5-P5) -> 210.81 | X5: =ABS(C5-Q5) -> 200.25
A6: 40182 | B6: 0 | C6: 21 | D6: 1152 | E6: 47 | F6: 168 | G6: 0 | H6: 17 | I6: 21 | J6: 0 | K6: 324 | L6: =AVERAGE(C3:C5) -> 215.33333 | M6: =(C6-L6) -> -194.33333 | N6: =ABS(M6) -> 194.33333 | O6: =($S$1*C5+(1-$S$1)*O5) -> 163.881 | P6: =($S$2*C5+(1-$S$2)*P5) -> 147.567 | Q6: =($S$3*C5+(1-$S$3)*Q5) -> 100.125 | V6: =ABS(C6-O6) -> 142.881 | W6: =ABS(C6-P6) -> 126.567 | X6: =ABS(C6-Q6) -> 79.125
A7: 40189 | B7: 0 | C7: 72 | D7: 928 | E7: 64 | F7: 233 | G7: 20 | H7: 23 | I7: 72 | J7: 0 | K7: 190 | L7: =AVERAGE(C4:C6) -> 7.6666667 | M7: =(C7-L7) -> 64.333333 | N7: =ABS(M7) -> 64.333333 | O7: =($S$1*C6+(1-$S$1)*O6) -> 149.5929 | P7: =($S$2*C6+(1-$S$2)*P6) -> 109.5969 | Q7: =($S$3*C6+(1-$S$3)*Q6) -> 60.5625 | V7: =ABS(C7-O7) -> 77.5929 | W7: =ABS(C7-P7) -> 37.5969 | X7: =ABS(C7-Q7) -> 11.4375
A8: 40196 | B8: 0 | C8: 23 | D8: 627 | E8: 49 | F8: 897 | G8: 3 | H8: 0 | I8: 23 | J8: 0 | K8: 479 | L8: =AVERAGE(C5:C7) -> 31 | M8: =(C8-L8) -> -8 | N8: =ABS(M8) -> 8 | O8: =($S$1*C7+(1-$S$1)*O7) -> 141.83361 | P8: =($S$2*C7+(1-$S$2)*P7) -> 98.31783 | Q8: =($S$3*C7+(1-$S$3)*Q7) -> 66.28125 | V8: =ABS(C8-O8) -> 118.83361 | W8: =ABS(C8-P8) -> 75.31783 | X8: =ABS(C8-Q8) -> 43.28125
A9: 40203 | B9: 0 | C9: 621 | D9: 864 | E9: 186 | F9: 211 | G9: 0 | H9: 0 | I9: 621 | J9: 114 | K9: 504 | L9: =AVERAGE(C6:C8) -> 38.666667 | M9: =(C9-L9) -> 582.33333 | N9: =ABS(M9) -> 582.33333 | O9: =($S$1*C8+(1-$S$1)*O8) -> 129.95025 | P9: =($S$2*C8+(1-$S$2)*P8) -> 75.722481 | Q9: =($S$3*C8+(1-$S$3)*Q8) -> 44.640625 | V9: =ABS(C9-O9) -> 491.04975 | W9: =ABS(C9-P9) -> 545.27752 | X9: =ABS(C9-Q9) -> 576.35938
A10: 40210 | B10: 0 | C10: 81 | D10: 488 | E10: 53 | F10: 274 | G10: 0 | H10: 24 | I10: 81 | J10: 338 | K10: 326 | L10: =AVERAGE(C7:C9) -> 238.66667 | M10: =(C10-L10) -> -157.66667 | N10: =ABS(M10) -> 157.66667 | O10: =($S$1*C9+(1-$S$1)*O9) -> 179.05522 | P10: =($S$2*C9+(1-$S$2)*P9) -> 239.30574 | Q10: =($S$3*C9+(1-$S$3)*Q9) -> 332.82031 | V10: =ABS(C10-O10) -> 98.055224 | W10: =ABS(C10-P10) -> 158.30574 | X10: =ABS(C10-Q10) -> 251.82031
A11: 40217 | B11: 0 | C11: 68 | D11: 547 | E11: 51 | F11: 512 | G11: 0 | H11: 0 | I11: 68 | J11: 314 | K11: 213 | L11: =AVERAGE(C8:C10) -> 241.66667 | M11: =(C11-L11) -> -173.66667 | N11: =ABS(M11) -> 173.66667 | O11: =($S$1*C10+(1-$S$1)*O10) -> 169.2497 | P11: =($S$2*C10+(1-$S$2)*P10) -> 191.81402 | Q11: =($S$3*C10+(1-$S$3)*Q10) -> 206.91016 | V11: =ABS(C11-O11) -> 101.2497 | W11: =ABS(C11-P11) -> 123.81402 | X11: =ABS(C11-Q11) -> 138.91016
A12: 40224 | B12: 0 | C12: 19 | D12: 1014 | E12: 159 | F12: 587 | G12: 0 | H12: 1 | I12: 19 | J12: 720 | K12: 442 | L12: =AVERAGE(C9:C11) -> 256.66667 | M12: =(C12-L12) -> -237.66667 | N12: =ABS(M12) -> 237.66667 | O12: =($S$1*C11+(1-$S$1)*O11) -> 159.12473 | P12: =($S$2*C11+(1-$S$2)*P11) -> 154.66981 | Q12: =($S$3*C11+(1-$S$3)*Q11) -> 137.45508 | V12: =ABS(C12-O12) -> 140.12473 | W12: =ABS(C12-P12) -> 135.66981 | X12: =ABS(C12-Q12) -> 118.45508
A13: 40231 | B13: 0 | C13: 1407 | D13: 613 | E13: 79 | F13: 294 | G13: 0 | H13: 0 | I13: 1407 | J13: 551 | K13: 272 | L13: =AVERAGE(C10:C12) -> 56 | M13: =(C13-L13) -> 1351 | N13: =ABS(M13) -> 1351 | O13: =($S$1*C12+(1-$S$1)*O12) -> 145.11226 | P13: =($S$2*C12+(1-$S$2)*P12) -> 113.96887 | Q13: =($S$3*C12+(1-$S$3)*Q12) -> 78.227539 | V13: =ABS(C13-O13) -> 1261.8877 | W13: =ABS(C13-P13) -> 1293.0311 | X13: =ABS(C13-Q13) -> 1328.7725
A14: 40238 | B14: 0 | C14: 133 | D14: 754 | E14: 78 | F14: 735 | G14: 3 | H14: 2 | I14: 133 | J14: 306 | K14: 409 | L14: =AVERAGE(C11:C13) -> 498 | M14: =(C14-L14) -> -365 | N14: =ABS(M14) -> 365 | O14: =($S$1*C13+(1-$S$1)*O13) -> 271.30103 | P14: =($S$2*C13+(1-$S$2)*P13) -> 501.87821 | Q14: =($S$3*C13+(1-$S$3)*Q13) -> 742.61377 | V14: =ABS(C14-O14) -> 138.30103 | W14: =ABS(C14-P14) -> 368.87821 | X14: =ABS(C14-Q14) -> 609.61377
A15: 40245 | B15: 0 | C15: 47 | D15: 800 | E15: 262 | F15: 917 | G15: 0 | H15: 0 | I15: 47 | J15: 405 | K15: 337 | L15: =AVERAGE(C12:C14) -> 519.66667 | M15: =(C15-L15) -> -472.66667 | N15: =ABS(M15) -> 472.66667 | O15: =($S$1*C14+(1-$S$1)*O14) -> 257.47093 | P15: =($S$2*C14+(1-$S$2)*P14) -> 391.21475 | Q15: =($S$3*C14+(1-$S$3)*Q14) -> 437.80688 | V15: =ABS(C15-O15) -> 210.47093 | W15: =ABS(C15-P15) -> 344.21475 | X15: =ABS(C15-Q15) -> 390.80688
A16: 40252 | B16: 194 | C16: 826 | D16: 555 | E16: 224 | F16: 551 | G16: 12 | H16: 0 | I16: 826 | J16: 179 | K16: 375 | L16: =AVERAGE(C13:C15) -> 529 | M16: =(C16-L16) -> 297 | N16: =ABS(M16) -> 297 | O16: =($S$1*C15+(1-$S$1)*O15) -> 236.42384 | P16: =($S$2*C15+(1-$S$2)*P15) -> 287.95032 | Q16: =($S$3*C15+(1-$S$3)*Q15) -> 242.40344 | V16: =ABS(C16-O16) -> 589.57616 | W16: =ABS(C16-P16) -> 538.04968 | X16: =ABS(C16-Q16) -> 583.59656
... A105: 40875 | B105: 226 | C105: 3275 | D105: 1040 | E105: 105 | F105: 953 | G105: 1564 | H105: 314 | I105: 3275 | J105: 436 | K105: 331 | L105: =AVERAGE(C102:C104) -> 3266.6667 | M105: =(C105-L105) -> 8.3333333 | N105: =ABS(M105) -> 8.3333333 | O105: =($S$1*C104+(1-$S$1)*O104) -> 1679.671 | P105: =($S$2*C104+(1-$S$2)*P104) -> 2547.9695 | Q105: =($S$3*C104+(1-$S$3)*Q104) -> 2843.1456 | V105: =ABS(C105-O105) -> 1595.329 | W105: =ABS(C105-P105) -> 727.03051 | X105: =ABS(C105-Q105) -> 431.85444
T106: MAD _M3 | U106: =AVERAGE(N94:N105) -> 555.66667
T107: MAD _ES_0.1 | U107: =AVERAGE(V94:V105) -> 906.81305
T108: MAD _ES_0.3 | U108: =AVERAGE(W94:W105) -> 698.18562
T109: MAD _ES_0.5 | U109: =AVERAGE(X94:X105) -> 646.26462
V111: AVERAGE | W111: STD DEV
V112: =AVERAGE(C2:C105) -> 799.71154 | W112: =STDEV(C2:C105) -> 903.03227

Sheet  REGENCY CAKESTAND 
A1: Week_start | B1: 22423 REGENCY CAKESTAND 3 TI | C1: 85123A WHITE HANGING HEART T- | D1: 85099B JUMBO BAG RED RETROSPO | E1: 47566 PARTY BUNTING | F1: 84879 ASSORTED COLOUR BIRD O | G1: 22086 PAPER CHAIN KIT 50'S C | H1: 79321 CHILLI LIGHTS | I1: 22197 SMALL POPCORN HOLDER | J1: 22386 JUMBO BAG PINK POLKADO | K1: 20725 LUNCH BAG RED RETROSPO | L1: MA3_FORECAST | M1: ERROR | N1: ABS ERROR | O1: ES_0.1 | P1: ES_0.3 | Q1: ES_0.5 | R1: ALPHA | S1: 0.1 | V1: ABSERR_0.1 | W1: ABSERR_0.3 | X1: ABSERR_0.5
A2: 40154 | B2: 0 | C2: 0 | D2: 1233 | E2: 19 | F2: 1213 | G2: 663 | H2: 175 | I2: 153 | J2: 0 | K2: 324 | O2: =(C2) -> 0 | P2: =(C2) -> 0 | Q2: =(C2) -> 0 | S2: 0.3
A3: 40161 | B3: 0 | C3: 0 | D3: 1304 | E3: 52 | F3: 1324 | G3: 572 | H3: 173 | I3: 644 | J3: 0 | K3: 236 | O3: =($S$1*C2+(1-$S$1)*O2) -> 0 | P3: =($S$2*C2+(1-$S$2)*P2) -> 0 | Q3: =($S$3*C2+(1-$S$3)*Q2) -> 0 | S3: 0.5 | V3: =ABS(C3-O3) -> 0 | W3: =ABS(C3-P3) -> 0 | X3: =ABS(C3-Q3) -> 0
A4: 40168 | B4: 0 | C4: 0 | D4: 36 | E4: 1 | F4: 82 | G4: 69 | H4: 19 | I4: 2 | J4: 0 | K4: 111 | O4: =($S$1*C3+(1-$S$1)*O3) -> 0 | P4: =($S$2*C3+(1-$S$2)*P3) -> 0 | Q4: =($S$3*C3+(1-$S$3)*Q3) -> 0 | V4: =ABS(C4-O4) -> 0 | W4: =ABS(C4-P4) -> 0 | X4: =ABS(C4-Q4) -> 0
A5: 40175 | B5: 0 | C5: 0 | D5: 0 | E5: 0 | F5: 0 | G5: 0 | H5: 0 | I5: 0 | J5: 0 | K5: 0 | L5: =AVERAGE(C2:C4) -> 0 | M5: =(C5-L5) -> 0 | N5: =ABS(M5) -> 0 | O5: =($S$1*C4+(1-$S$1)*O4) -> 0 | P5: =($S$2*C4+(1-$S$2)*P4) -> 0 | Q5: =($S$3*C4+(1-$S$3)*Q4) -> 0 | V5: =ABS(C5-O5) -> 0 | W5: =ABS(C5-P5) -> 0 | X5: =ABS(C5-Q5) -> 0
A6: 40182 | B6: 0 | C6: 0 | D6: 1152 | E6: 47 | F6: 168 | G6: 0 | H6: 17 | I6: 21 | J6: 0 | K6: 324 | L6: =AVERAGE(C3:C5) -> 0 | M6: =(C6-L6) -> 0 | N6: =ABS(M6) -> 0 | O6: =($S$1*C5+(1-$S$1)*O5) -> 0 | P6: =($S$2*C5+(1-$S$2)*P5) -> 0 | Q6: =($S$3*C5+(1-$S$3)*Q5) -> 0 | V6: =ABS(C6-O6) -> 0 | W6: =ABS(C6-P6) -> 0 | X6: =ABS(C6-Q6) -> 0
A7: 40189 | B7: 0 | C7: 0 | D7: 928 | E7: 64 | F7: 233 | G7: 20 | H7: 23 | I7: 72 | J7: 0 | K7: 190 | L7: =AVERAGE(C4:C6) -> 0 | M7: =(C7-L7) -> 0 | N7: =ABS(M7) -> 0 | O7: =($S$1*C6+(1-$S$1)*O6) -> 0 | P7: =($S$2*C6+(1-$S$2)*P6) -> 0 | Q7: =($S$3*C6+(1-$S$3)*Q6) -> 0 | V7: =ABS(C7-O7) -> 0 | W7: =ABS(C7-P7) -> 0 | X7: =ABS(C7-Q7) -> 0
A8: 40196 | B8: 0 | C8: 0 | D8: 627 | E8: 49 | F8: 897 | G8: 3 | H8: 0 | I8: 23 | J8: 0 | K8: 479 | L8: =AVERAGE(C5:C7) -> 0 | M8: =(C8-L8) -> 0 | N8: =ABS(M8) -> 0 | O8: =($S$1*C7+(1-$S$1)*O7) -> 0 | P8: =($S$2*C7+(1-$S$2)*P7) -> 0 | Q8: =($S$3*C7+(1-$S$3)*Q7) -> 0 | V8: =ABS(C8-O8) -> 0 | W8: =ABS(C8-P8) -> 0 | X8: =ABS(C8-Q8) -> 0
A9: 40203 | B9: 0 | C9: 0 | D9: 864 | E9: 186 | F9: 211 | G9: 0 | H9: 0 | I9: 621 | J9: 114 | K9: 504 | L9: =AVERAGE(C6:C8) -> 0 | M9: =(C9-L9) -> 0 | N9: =ABS(M9) -> 0 | O9: =($S$1*C8+(1-$S$1)*O8) -> 0 | P9: =($S$2*C8+(1-$S$2)*P8) -> 0 | Q9: =($S$3*C8+(1-$S$3)*Q8) -> 0 | V9: =ABS(C9-O9) -> 0 | W9: =ABS(C9-P9) -> 0 | X9: =ABS(C9-Q9) -> 0
A10: 40210 | B10: 0 | C10: 0 | D10: 488 | E10: 53 | F10: 274 | G10: 0 | H10: 24 | I10: 81 | J10: 338 | K10: 326 | L10: =AVERAGE(C7:C9) -> 0 | M10: =(C10-L10) -> 0 | N10: =ABS(M10) -> 0 | O10: =($S$1*C9+(1-$S$1)*O9) -> 0 | P10: =($S$2*C9+(1-$S$2)*P9) -> 0 | Q10: =($S$3*C9+(1-$S$3)*Q9) -> 0 | V10: =ABS(C10-O10) -> 0 | W10: =ABS(C10-P10) -> 0 | X10: =ABS(C10-Q10) -> 0
A11: 40217 | B11: 0 | C11: 0 | D11: 547 | E11: 51 | F11: 512 | G11: 0 | H11: 0 | I11: 68 | J11: 314 | K11: 213 | L11: =AVERAGE(C8:C10) -> 0 | M11: =(C11-L11) -> 0 | N11: =ABS(M11) -> 0 | O11: =($S$1*C10+(1-$S$1)*O10) -> 0 | P11: =($S$2*C10+(1-$S$2)*P10) -> 0 | Q11: =($S$3*C10+(1-$S$3)*Q10) -> 0 | V11: =ABS(C11-O11) -> 0 | W11: =ABS(C11-P11) -> 0 | X11: =ABS(C11-Q11) -> 0
A12: 40224 | B12: 0 | C12: 0 | D12: 1014 | E12: 159 | F12: 587 | G12: 0 | H12: 1 | I12: 19 | J12: 720 | K12: 442 | L12: =AVERAGE(C9:C11) -> 0 | M12: =(C12-L12) -> 0 | N12: =ABS(M12) -> 0 | O12: =($S$1*C11+(1-$S$1)*O11) -> 0 | P12: =($S$2*C11+(1-$S$2)*P11) -> 0 | Q12: =($S$3*C11+(1-$S$3)*Q11) -> 0 | V12: =ABS(C12-O12) -> 0 | W12: =ABS(C12-P12) -> 0 | X12: =ABS(C12-Q12) -> 0
A13: 40231 | B13: 0 | C13: 0 | D13: 613 | E13: 79 | F13: 294 | G13: 0 | H13: 0 | I13: 1407 | J13: 551 | K13: 272 | L13: =AVERAGE(C10:C12) -> 0 | M13: =(C13-L13) -> 0 | N13: =ABS(M13) -> 0 | O13: =($S$1*C12+(1-$S$1)*O12) -> 0 | P13: =($S$2*C12+(1-$S$2)*P12) -> 0 | Q13: =($S$3*C12+(1-$S$3)*Q12) -> 0 | V13: =ABS(C13-O13) -> 0 | W13: =ABS(C13-P13) -> 0 | X13: =ABS(C13-Q13) -> 0
A14: 40238 | B14: 0 | C14: 0 | D14: 754 | E14: 78 | F14: 735 | G14: 3 | H14: 2 | I14: 133 | J14: 306 | K14: 409 | L14: =AVERAGE(C11:C13) -> 0 | M14: =(C14-L14) -> 0 | N14: =ABS(M14) -> 0 | O14: =($S$1*C13+(1-$S$1)*O13) -> 0 | P14: =($S$2*C13+(1-$S$2)*P13) -> 0 | Q14: =($S$3*C13+(1-$S$3)*Q13) -> 0 | V14: =ABS(C14-O14) -> 0 | W14: =ABS(C14-P14) -> 0 | X14: =ABS(C14-Q14) -> 0
A15: 40245 | B15: 0 | C15: 0 | D15: 800 | E15: 262 | F15: 917 | G15: 0 | H15: 0 | I15: 47 | J15: 405 | K15: 337 | L15: =AVERAGE(C12:C14) -> 0 | M15: =(C15-L15) -> 0 | N15: =ABS(M15) -> 0 | O15: =($S$1*C14+(1-$S$1)*O14) -> 0 | P15: =($S$2*C14+(1-$S$2)*P14) -> 0 | Q15: =($S$3*C14+(1-$S$3)*Q14) -> 0 | V15: =ABS(C15-O15) -> 0 | W15: =ABS(C15-P15) -> 0 | X15: =ABS(C15-Q15) -> 0
A16: 40252 | B16: 194 | C16: 194 | D16: 555 | E16: 224 | F16: 551 | G16: 12 | H16: 0 | I16: 826 | J16: 179 | K16: 375 | L16: =AVERAGE(C13:C15) -> 0 | M16: =(C16-L16) -> 194 | N16: =ABS(M16) -> 194 | O16: =($S$1*C15+(1-$S$1)*O15) -> 0 | P16: =($S$2*C15+(1-$S$2)*P15) -> 0 | Q16: =($S$3*C15+(1-$S$3)*Q15) -> 0 | V16: =ABS(C16-O16) -> 194 | W16: =ABS(C16-P16) -> 194 | X16: =ABS(C16-Q16) -> 194
... A105: 40875 | B105: 226 | C105: 226 | D105: 1040 | E105: 105 | F105: 953 | G105: 1564 | H105: 314 | I105: 3275 | J105: 436 | K105: 331 | L105: =AVERAGE(C102:C104) -> 217 | M105: =(C105-L105) -> 9 | N105: =ABS(M105) -> 9 | O105: =($S$1*C104+(1-$S$1)*O104) -> 220.78658 | P105: =($S$2*C104+(1-$S$2)*P104) -> 226.86719 | Q105: =($S$3*C104+(1-$S$3)*Q104) -> 233.60103 | V105: =ABS(C105-O105) -> 5.2134245 | W105: =ABS(C105-P105) -> 0.8671919 | X105: =ABS(C105-Q105) -> 7.6010286
T106: MAD _M3 | U106: =AVERAGE(N94:N105) -> 64.027778
T107: MAD _ES_0.1 | U107: =AVERAGE(V94:V105) -> 57.697315
T108: MAD _ES_0.3 | U108: =AVERAGE(W94:W105) -> 62.545069
T109: MAD _ES_0.5 | U109: =AVERAGE(X94:X105) -> 70.77462
V111: AVERAGE | W111: STD DEV
V112: =AVERAGE(C2:C105) -> 244.35577 | W112: =STDEV(C2:C105) -> 178.33686

Sheet CHILLI LIGHTS
A1: Week_start | B1: 22423 REGENCY CAKESTAND 3 TI | C1: 85123A WHITE HANGING HEART T- | D1: 85099B JUMBO BAG RED RETROSPO | E1: 47566 PARTY BUNTING | F1: 84879 ASSORTED COLOUR BIRD O | G1: 22086 PAPER CHAIN KIT 50'S C | H1: 79321 CHILLI LIGHTS | I1: 22197 SMALL POPCORN HOLDER | J1: 22386 JUMBO BAG PINK POLKADO | K1: 20725 LUNCH BAG RED RETROSPO | L1: MA3_FORECAST | M1: ERROR | N1: ABS ERROR | O1: ES_0.1 | P1: ES_0.3 | Q1: ES_0.5 | R1: ALPHA | S1: 0.1 | V1: ABSERR_0.1 | W1: ABSERR_0.3 | X1: ABSERR_0.5
A2: 40154 | B2: 0 | C2: 175 | D2: 1233 | E2: 19 | F2: 1213 | G2: 663 | H2: 175 | I2: 153 | J2: 0 | K2: 324 | O2: =(C2) -> 175 | P2: =(C2) -> 175 | Q2: =(C2) -> 175 | S2: 0.3
A3: 40161 | B3: 0 | C3: 173 | D3: 1304 | E3: 52 | F3: 1324 | G3: 572 | H3: 173 | I3: 644 | J3: 0 | K3: 236 | O3: =($S$1*C2+(1-$S$1)*O2) -> 175 | P3: =($S$2*C2+(1-$S$2)*P2) -> 175 | Q3: =($S$3*C2+(1-$S$3)*Q2) -> 175 | S3: 0.5 | V3: =ABS(C3-O3) -> 2 | W3: =ABS(C3-P3) -> 2 | X3: =ABS(C3-Q3) -> 2
A4: 40168 | B4: 0 | C4: 19 | D4: 36 | E4: 1 | F4: 82 | G4: 69 | H4: 19 | I4: 2 | J4: 0 | K4: 111 | O4: =($S$1*C3+(1-$S$1)*O3) -> 174.8 | P4: =($S$2*C3+(1-$S$2)*P3) -> 174.4 | Q4: =($S$3*C3+(1-$S$3)*Q3) -> 174 | V4: =ABS(C4-O4) -> 155.8 | W4: =ABS(C4-P4) -> 155.4 | X4: =ABS(C4-Q4) -> 155
A5: 40175 | B5: 0 | C5: 0 | D5: 0 | E5: 0 | F5: 0 | G5: 0 | H5: 0 | I5: 0 | J5: 0 | K5: 0 | L5: =AVERAGE(C2:C4) -> 122.33333 | M5: =(C5-L5) -> -122.33333 | N5: =ABS(M5) -> 122.33333 | O5: =($S$1*C4+(1-$S$1)*O4) -> 159.22 | P5: =($S$2*C4+(1-$S$2)*P4) -> 127.78 | Q5: =($S$3*C4+(1-$S$3)*Q4) -> 96.5 | V5: =ABS(C5-O5) -> 159.22 | W5: =ABS(C5-P5) -> 127.78 | X5: =ABS(C5-Q5) -> 96.5
A6: 40182 | B6: 0 | C6: 17 | D6: 1152 | E6: 47 | F6: 168 | G6: 0 | H6: 17 | I6: 21 | J6: 0 | K6: 324 | L6: =AVERAGE(C3:C5) -> 64 | M6: =(C6-L6) -> -47 | N6: =ABS(M6) -> 47 | O6: =($S$1*C5+(1-$S$1)*O5) -> 143.298 | P6: =($S$2*C5+(1-$S$2)*P5) -> 89.446 | Q6: =($S$3*C5+(1-$S$3)*Q5) -> 48.25 | V6: =ABS(C6-O6) -> 126.298 | W6: =ABS(C6-P6) -> 72.446 | X6: =ABS(C6-Q6) -> 31.25
A7: 40189 | B7: 0 | C7: 23 | D7: 928 | E7: 64 | F7: 233 | G7: 20 | H7: 23 | I7: 72 | J7: 0 | K7: 190 | L7: =AVERAGE(C4:C6) -> 12 | M7: =(C7-L7) -> 11 | N7: =ABS(M7) -> 11 | O7: =($S$1*C6+(1-$S$1)*O6) -> 130.6682 | P7: =($S$2*C6+(1-$S$2)*P6) -> 67.7122 | Q7: =($S$3*C6+(1-$S$3)*Q6) -> 32.625 | V7: =ABS(C7-O7) -> 107.6682 | W7: =ABS(C7-P7) -> 44.7122 | X7: =ABS(C7-Q7) -> 9.625
A8: 40196 | B8: 0 | C8: 0 | D8: 627 | E8: 49 | F8: 897 | G8: 3 | H8: 0 | I8: 23 | J8: 0 | K8: 479 | L8: =AVERAGE(C5:C7) -> 13.333333 | M8: =(C8-L8) -> -13.333333 | N8: =ABS(M8) -> 13.333333 | O8: =($S$1*C7+(1-$S$1)*O7) -> 119.90138 | P8: =($S$2*C7+(1-$S$2)*P7) -> 54.29854 | Q8: =($S$3*C7+(1-$S$3)*Q7) -> 27.8125 | V8: =ABS(C8-O8) -> 119.90138 | W8: =ABS(C8-P8) -> 54.29854 | X8: =ABS(C8-Q8) -> 27.8125
A9: 40203 | B9: 0 | C9: 0 | D9: 864 | E9: 186 | F9: 211 | G9: 0 | H9: 0 | I9: 621 | J9: 114 | K9: 504 | L9: =AVERAGE(C6:C8) -> 13.333333 | M9: =(C9-L9) -> -13.333333 | N9: =ABS(M9) -> 13.333333 | O9: =($S$1*C8+(1-$S$1)*O8) -> 107.91124 | P9: =($S$2*C8+(1-$S$2)*P8) -> 38.008978 | Q9: =($S$3*C8+(1-$S$3)*Q8) -> 13.90625 | V9: =ABS(C9-O9) -> 107.91124 | W9: =ABS(C9-P9) -> 38.008978 | X9: =ABS(C9-Q9) -> 13.90625
A10: 40210 | B10: 0 | C10: 24 | D10: 488 | E10: 53 | F10: 274 | G10: 0 | H10: 24 | I10: 81 | J10: 338 | K10: 326 | L10: =AVERAGE(C7:C9) -> 7.6666667 | M10: =(C10-L10) -> 16.333333 | N10: =ABS(M10) -> 16.333333 | O10: =($S$1*C9+(1-$S$1)*O9) -> 97.120118 | P10: =($S$2*C9+(1-$S$2)*P9) -> 26.606285 | Q10: =($S$3*C9+(1-$S$3)*Q9) -> 6.953125 | V10: =ABS(C10-O10) -> 73.120118 | W10: =ABS(C10-P10) -> 2.6062846 | X10: =ABS(C10-Q10) -> 17.046875
A11: 40217 | B11: 0 | C11: 0 | D11: 547 | E11: 51 | F11: 512 | G11: 0 | H11: 0 | I11: 68 | J11: 314 | K11: 213 | L11: =AVERAGE(C8:C10) -> 8 | M11: =(C11-L11) -> -8 | N11: =ABS(M11) -> 8 | O11: =($S$1*C10+(1-$S$1)*O10) -> 89.808106 | P11: =($S$2*C10+(1-$S$2)*P10) -> 25.824399 | Q11: =($S$3*C10+(1-$S$3)*Q10) -> 15.476562 | V11: =ABS(C11-O11) -> 89.808106 | W11: =ABS(C11-P11) -> 25.824399 | X11: =ABS(C11-Q11) -> 15.476562
A12: 40224 | B12: 0 | C12: 1 | D12: 1014 | E12: 159 | F12: 587 | G12: 0 | H12: 1 | I12: 19 | J12: 720 | K12: 442 | L12: =AVERAGE(C9:C11) -> 8 | M12: =(C12-L12) -> -7 | N12: =ABS(M12) -> 7 | O12: =($S$1*C11+(1-$S$1)*O11) -> 80.827295 | P12: =($S$2*C11+(1-$S$2)*P11) -> 18.077079 | Q12: =($S$3*C11+(1-$S$3)*Q11) -> 7.7382812 | V12: =ABS(C12-O12) -> 79.827295 | W12: =ABS(C12-P12) -> 17.077079 | X12: =ABS(C12-Q12) -> 6.7382812
A13: 40231 | B13: 0 | C13: 0 | D13: 613 | E13: 79 | F13: 294 | G13: 0 | H13: 0 | I13: 1407 | J13: 551 | K13: 272 | L13: =AVERAGE(C10:C12) -> 8.3333333 | M13: =(C13-L13) -> -8.3333333 | N13: =ABS(M13) -> 8.3333333 | O13: =($S$1*C12+(1-$S$1)*O12) -> 72.844566 | P13: =($S$2*C12+(1-$S$2)*P12) -> 12.953956 | Q13: =($S$3*C12+(1-$S$3)*Q12) -> 4.3691406 | V13: =ABS(C13-O13) -> 72.844566 | W13: =ABS(C13-P13) -> 12.953956 | X13: =ABS(C13-Q13) -> 4.3691406
A14: 40238 | B14: 0 | C14: 2 | D14: 754 | E14: 78 | F14: 735 | G14: 3 | H14: 2 | I14: 133 | J14: 306 | K14: 409 | L14: =AVERAGE(C11:C13) -> 0.33333333 | M14: =(C14-L14) -> 1.6666667 | N14: =ABS(M14) -> 1.6666667 | O14: =($S$1*C13+(1-$S$1)*O13) -> 65.560109 | P14: =($S$2*C13+(1-$S$2)*P13) -> 9.0677689 | Q14: =($S$3*C13+(1-$S$3)*Q13) -> 2.1845703 | V14: =ABS(C14-O14) -> 63.560109 | W14: =ABS(C14-P14) -> 7.0677689 | X14: =ABS(C14-Q14) -> 0.18457031
A15: 40245 | B15: 0 | C15: 0 | D15: 800 | E15: 262 | F15: 917 | G15: 0 | H15: 0 | I15: 47 | J15: 405 | K15: 337 | L15: =AVERAGE(C12:C14) -> 1 | M15: =(C15-L15) -> -1 | N15: =ABS(M15) -> 1 | O15: =($S$1*C14+(1-$S$1)*O14) -> 59.204098 | P15: =($S$2*C14+(1-$S$2)*P14) -> 6.9474383 | Q15: =($S$3*C14+(1-$S$3)*Q14) -> 2.0922852 | V15: =ABS(C15-O15) -> 59.204098 | W15: =ABS(C15-P15) -> 6.9474383 | X15: =ABS(C15-Q15) -> 2.0922852
A16: 40252 | B16: 194 | C16: 0 | D16: 555 | E16: 224 | F16: 551 | G16: 12 | H16: 0 | I16: 826 | J16: 179 | K16: 375 | L16: =AVERAGE(C13:C15) -> 0.66666667 | M16: =(C16-L16) -> -0.66666667 | N16: =ABS(M16) -> 0.66666667 | O16: =($S$1*C15+(1-$S$1)*O15) -> 53.283689 | P16: =($S$2*C15+(1-$S$2)*P15) -> 4.8632068 | Q16: =($S$3*C15+(1-$S$3)*Q15) -> 1.0461426 | V16: =ABS(C16-O16) -> 53.283689 | W16: =ABS(C16-P16) -> 4.8632068 | X16: =ABS(C16-Q16) -> 1.0461426
... A105: 40875 | B105: 226 | C105: 314 | D105: 1040 | E105: 105 | F105: 953 | G105: 1564 | H105: 314 | I105: 3275 | J105: 436 | K105: 331 | L105: =AVERAGE(C102:C104) -> 610 | M105: =(C105-L105) -> -296 | N105: =ABS(M105) -> 296 | O105: =($S$1*C104+(1-$S$1)*O104) -> 285.75988 | P105: =($S$2*C104+(1-$S$2)*P104) -> 508.37837 | Q105: =($S$3*C104+(1-$S$3)*Q104) -> 664.44653 | V105: =ABS(C105-O105) -> 28.24012 | W105: =ABS(C105-P105) -> 194.37837 | X105: =ABS(C105-Q105) -> 350.44653
T106: MAD _M3 | U106: =AVERAGE(N94:N105) -> 173.75
T107: MAD _ES_0.1 | U107: =AVERAGE(V94:V105) -> 167.71517
T108: MAD _ES_0.3 | U108: =AVERAGE(W94:W105) -> 169.35865
T109: MAD _ES_0.5 | U109: =AVERAGE(X94:X105) -> 181.40984
V111: AVERAGE | W111: STD DEV
V112: =AVERAGE(C2:C105) -> 148.25 | W112: =STDEV(C2:C105) -> 190.58514

Sheet PAPER CHAIN KIT
A1: Week_start | B1: 22423 REGENCY CAKESTAND 3 TI | C1: 85123A WHITE HANGING HEART T- | D1: 85099B JUMBO BAG RED RETROSPO | E1: 47566 PARTY BUNTING | F1: 84879 ASSORTED COLOUR BIRD O | G1: 22086 PAPER CHAIN KIT 50'S C | H1: 79321 CHILLI LIGHTS | I1: 22197 SMALL POPCORN HOLDER | J1: 22386 JUMBO BAG PINK POLKADO | K1: 20725 LUNCH BAG RED RETROSPO | L1: MA3_FORECAST | M1: ERROR | N1: ABS ERROR | O1: ES_0.1 | P1: ES_0.3 | Q1: ES_0.5 | R1: ALPHA | S1: 0.1 | V1: ABSERR_0.1 | W1: ABSERR_0.3 | X1: ABSERR_0.5
A2: 40154 | B2: 0 | C2: 663 | D2: 1233 | E2: 19 | F2: 1213 | G2: 663 | H2: 175 | I2: 153 | J2: 0 | K2: 324 | O2: =(C2) -> 663 | P2: =(C2) -> 663 | Q2: =(C2) -> 663 | S2: 0.3
A3: 40161 | B3: 0 | C3: 572 | D3: 1304 | E3: 52 | F3: 1324 | G3: 572 | H3: 173 | I3: 644 | J3: 0 | K3: 236 | O3: =($S$1*C2+(1-$S$1)*O2) -> 663 | P3: =($S$2*C2+(1-$S$2)*P2) -> 663 | Q3: =($S$3*C2+(1-$S$3)*Q2) -> 663 | S3: 0.5 | V3: =ABS(C3-O3) -> 91 | W3: =ABS(C3-P3) -> 91 | X3: =ABS(C3-Q3) -> 91
A4: 40168 | B4: 0 | C4: 69 | D4: 36 | E4: 1 | F4: 82 | G4: 69 | H4: 19 | I4: 2 | J4: 0 | K4: 111 | O4: =($S$1*C3+(1-$S$1)*O3) -> 653.9 | P4: =($S$2*C3+(1-$S$2)*P3) -> 635.7 | Q4: =($S$3*C3+(1-$S$3)*Q3) -> 617.5 | V4: =ABS(C4-O4) -> 584.9 | W4: =ABS(C4-P4) -> 566.7 | X4: =ABS(C4-Q4) -> 548.5
A5: 40175 | B5: 0 | C5: 0 | D5: 0 | E5: 0 | F5: 0 | G5: 0 | H5: 0 | I5: 0 | J5: 0 | K5: 0 | L5: =AVERAGE(C2:C4) -> 434.66667 | M5: =(C5-L5) -> -434.66667 | N5: =ABS(M5) -> 434.66667 | O5: =($S$1*C4+(1-$S$1)*O4) -> 595.41 | P5: =($S$2*C4+(1-$S$2)*P4) -> 465.69 | Q5: =($S$3*C4+(1-$S$3)*Q4) -> 343.25 | V5: =ABS(C5-O5) -> 595.41 | W5: =ABS(C5-P5) -> 465.69 | X5: =ABS(C5-Q5) -> 343.25
A6: 40182 | B6: 0 | C6: 0 | D6: 1152 | E6: 47 | F6: 168 | G6: 0 | H6: 17 | I6: 21 | J6: 0 | K6: 324 | L6: =AVERAGE(C3:C5) -> 213.66667 | M6: =(C6-L6) -> -213.66667 | N6: =ABS(M6) -> 213.66667 | O6: =($S$1*C5+(1-$S$1)*O5) -> 535.869 | P6: =($S$2*C5+(1-$S$2)*P5) -> 325.983 | Q6: =($S$3*C5+(1-$S$3)*Q5) -> 171.625 | V6: =ABS(C6-O6) -> 535.869 | W6: =ABS(C6-P6) -> 325.983 | X6: =ABS(C6-Q6) -> 171.625
A7: 40189 | B7: 0 | C7: 20 | D7: 928 | E7: 64 | F7: 233 | G7: 20 | H7: 23 | I7: 72 | J7: 0 | K7: 190 | L7: =AVERAGE(C4:C6) -> 23 | M7: =(C7-L7) -> -3 | N7: =ABS(M7) -> 3 | O7: =($S$1*C6+(1-$S$1)*O6) -> 482.2821 | P7: =($S$2*C6+(1-$S$2)*P6) -> 228.1881 | Q7: =($S$3*C6+(1-$S$3)*Q6) -> 85.8125 | V7: =ABS(C7-O7) -> 462.2821 | W7: =ABS(C7-P7) -> 208.1881 | X7: =ABS(C7-Q7) -> 65.8125
A8: 40196 | B8: 0 | C8: 3 | D8: 627 | E8: 49 | F8: 897 | G8: 3 | H8: 0 | I8: 23 | J8: 0 | K8: 479 | L8: =AVERAGE(C5:C7) -> 6.6666667 | M8: =(C8-L8) -> -3.6666667 | N8: =ABS(M8) -> 3.6666667 | O8: =($S$1*C7+(1-$S$1)*O7) -> 436.05389 | P8: =($S$2*C7+(1-$S$2)*P7) -> 165.73167 | Q8: =($S$3*C7+(1-$S$3)*Q7) -> 52.90625 | V8: =ABS(C8-O8) -> 433.05389 | W8: =ABS(C8-P8) -> 162.73167 | X8: =ABS(C8-Q8) -> 49.90625
A9: 40203 | B9: 0 | C9: 0 | D9: 864 | E9: 186 | F9: 211 | G9: 0 | H9: 0 | I9: 621 | J9: 114 | K9: 504 | L9: =AVERAGE(C6:C8) -> 7.6666667 | M9: =(C9-L9) -> -7.6666667 | N9: =ABS(M9) -> 7.6666667 | O9: =($S$1*C8+(1-$S$1)*O8) -> 392.7485 | P9: =($S$2*C8+(1-$S$2)*P8) -> 116.91217 | Q9: =($S$3*C8+(1-$S$3)*Q8) -> 27.953125 | V9: =ABS(C9-O9) -> 392.7485 | W9: =ABS(C9-P9) -> 116.91217 | X9: =ABS(C9-Q9) -> 27.953125
A10: 40210 | B10: 0 | C10: 0 | D10: 488 | E10: 53 | F10: 274 | G10: 0 | H10: 24 | I10: 81 | J10: 338 | K10: 326 | L10: =AVERAGE(C7:C9) -> 7.6666667 | M10: =(C10-L10) -> -7.6666667 | N10: =ABS(M10) -> 7.6666667 | O10: =($S$1*C9+(1-$S$1)*O9) -> 353.47365 | P10: =($S$2*C9+(1-$S$2)*P9) -> 81.838518 | Q10: =($S$3*C9+(1-$S$3)*Q9) -> 13.976562 | V10: =ABS(C10-O10) -> 353.47365 | W10: =ABS(C10-P10) -> 81.838518 | X10: =ABS(C10-Q10) -> 13.976562
A11: 40217 | B11: 0 | C11: 0 | D11: 547 | E11: 51 | F11: 512 | G11: 0 | H11: 0 | I11: 68 | J11: 314 | K11: 213 | L11: =AVERAGE(C8:C10) -> 1 | M11: =(C11-L11) -> -1 | N11: =ABS(M11) -> 1 | O11: =($S$1*C10+(1-$S$1)*O10) -> 318.12629 | P11: =($S$2*C10+(1-$S$2)*P10) -> 57.286963 | Q11: =($S$3*C10+(1-$S$3)*Q10) -> 6.9882812 | V11: =ABS(C11-O11) -> 318.12629 | W11: =ABS(C11-P11) -> 57.286963 | X11: =ABS(C11-Q11) -> 6.9882812
A12: 40224 | B12: 0 | C12: 0 | D12: 1014 | E12: 159 | F12: 587 | G12: 0 | H12: 1 | I12: 19 | J12: 720 | K12: 442 | L12: =AVERAGE(C9:C11) -> 0 | M12: =(C12-L12) -> 0 | N12: =ABS(M12) -> 0 | O12: =($S$1*C11+(1-$S$1)*O11) -> 286.31366 | P12: =($S$2*C11+(1-$S$2)*P11) -> 40.100874 | Q12: =($S$3*C11+(1-$S$3)*Q11) -> 3.4941406 | V12: =ABS(C12-O12) -> 286.31366 | W12: =ABS(C12-P12) -> 40.100874 | X12: =ABS(C12-Q12) -> 3.4941406
A13: 40231 | B13: 0 | C13: 0 | D13: 613 | E13: 79 | F13: 294 | G13: 0 | H13: 0 | I13: 1407 | J13: 551 | K13: 272 | L13: =AVERAGE(C10:C12) -> 0 | M13: =(C13-L13) -> 0 | N13: =ABS(M13) -> 0 | O13: =($S$1*C12+(1-$S$1)*O12) -> 257.68229 | P13: =($S$2*C12+(1-$S$2)*P12) -> 28.070612 | Q13: =($S$3*C12+(1-$S$3)*Q12) -> 1.7470703 | V13: =ABS(C13-O13) -> 257.68229 | W13: =ABS(C13-P13) -> 28.070612 | X13: =ABS(C13-Q13) -> 1.7470703
A14: 40238 | B14: 0 | C14: 3 | D14: 754 | E14: 78 | F14: 735 | G14: 3 | H14: 2 | I14: 133 | J14: 306 | K14: 409 | L14: =AVERAGE(C11:C13) -> 0 | M14: =(C14-L14) -> 3 | N14: =ABS(M14) -> 3 | O14: =($S$1*C13+(1-$S$1)*O13) -> 231.91406 | P14: =($S$2*C13+(1-$S$2)*P13) -> 19.649428 | Q14: =($S$3*C13+(1-$S$3)*Q13) -> 0.87353516 | V14: =ABS(C14-O14) -> 228.91406 | W14: =ABS(C14-P14) -> 16.649428 | X14: =ABS(C14-Q14) -> 2.1264648
A15: 40245 | B15: 0 | C15: 0 | D15: 800 | E15: 262 | F15: 917 | G15: 0 | H15: 0 | I15: 47 | J15: 405 | K15: 337 | L15: =AVERAGE(C12:C14) -> 1 | M15: =(C15-L15) -> -1 | N15: =ABS(M15) -> 1 | O15: =($S$1*C14+(1-$S$1)*O14) -> 209.02266 | P15: =($S$2*C14+(1-$S$2)*P14) -> 14.6546 | Q15: =($S$3*C14+(1-$S$3)*Q14) -> 1.9367676 | V15: =ABS(C15-O15) -> 209.02266 | W15: =ABS(C15-P15) -> 14.6546 | X15: =ABS(C15-Q15) -> 1.9367676
A16: 40252 | B16: 194 | C16: 12 | D16: 555 | E16: 224 | F16: 551 | G16: 12 | H16: 0 | I16: 826 | J16: 179 | K16: 375 | L16: =AVERAGE(C13:C15) -> 1 | M16: =(C16-L16) -> 11 | N16: =ABS(M16) -> 11 | O16: =($S$1*C15+(1-$S$1)*O15) -> 188.12039 | P16: =($S$2*C15+(1-$S$2)*P15) -> 10.25822 | Q16: =($S$3*C15+(1-$S$3)*Q15) -> 0.96838379 | V16: =ABS(C16-O16) -> 176.12039 | W16: =ABS(C16-P16) -> 1.7417802 | X16: =ABS(C16-Q16) -> 11.031616
... A105: 40875 | B105: 226 | C105: 1564 | D105: 1040 | E105: 105 | F105: 953 | G105: 1564 | H105: 314 | I105: 3275 | J105: 436 | K105: 331 | L105: =AVERAGE(C102:C104) -> 1763 | M105: =(C105-L105) -> -199 | N105: =ABS(M105) -> 199 | O105: =($S$1*C104+(1-$S$1)*O104) -> 878.01448 | P105: =($S$2*C104+(1-$S$2)*P104) -> 1509.1684 | Q105: =($S$3*C104+(1-$S$3)*Q104) -> 1718.043 | V105: =ABS(C105-O105) -> 685.98552 | W105: =ABS(C105-P105) -> 54.83161 | X105: =ABS(C105-Q105) -> 154.04299
T106: MAD _M3 | U106: =AVERAGE(N94:N105) -> 343
T107: MAD _ES_0.1 | U107: =AVERAGE(V94:V105) -> 683.78174
T108: MAD _ES_0.3 | U108: =AVERAGE(W94:W105) -> 375.19523
T109: MAD _ES_0.5 | U109: =AVERAGE(X94:X105) -> 301.583
V111: AVERAGE | W111: STD DEV
V112: =AVERAGE(C2:C105) -> 299.125 | W112: =STDEV(C2:C105) -> 522.80013

Sheet PARTY BUNTING
A1: Week_start | B1: 22423 REGENCY CAKESTAND 3 TI | C1: 85123A WHITE HANGING HEART T- | D1: 85099B JUMBO BAG RED RETROSPO | E1: 47566 PARTY BUNTING | F1: 84879 ASSORTED COLOUR BIRD O | G1: 22086 PAPER CHAIN KIT 50'S C | H1: 79321 CHILLI LIGHTS | I1: 22197 SMALL POPCORN HOLDER | J1: 22386 JUMBO BAG PINK POLKADO | K1: 20725 LUNCH BAG RED RETROSPO | L1: MA3_FORECAST | M1: ERROR | N1: ABS ERROR | O1: ES_0.1 | P1: ES_0.3 | Q1: ES_0.5 | R1: ALPHA | S1: 0.1 | V1: ABSERR_0.1 | W1: ABSERR_0.3 | X1: ABSERR_0.5
A2: 40154 | B2: 0 | C2: 19 | D2: 1233 | E2: 19 | F2: 1213 | G2: 663 | H2: 175 | I2: 153 | J2: 0 | K2: 324 | O2: =(C2) -> 19 | P2: =(C2) -> 19 | Q2: =(C2) -> 19 | S2: 0.3
A3: 40161 | B3: 0 | C3: 52 | D3: 1304 | E3: 52 | F3: 1324 | G3: 572 | H3: 173 | I3: 644 | J3: 0 | K3: 236 | O3: =($S$1*C2+(1-$S$1)*O2) -> 19 | P3: =($S$2*C2+(1-$S$2)*P2) -> 19 | Q3: =($S$3*C2+(1-$S$3)*Q2) -> 19 | S3: 0.5 | V3: =ABS(C3-O3) -> 33 | W3: =ABS(C3-P3) -> 33 | X3: =ABS(C3-Q3) -> 33
A4: 40168 | B4: 0 | C4: 1 | D4: 36 | E4: 1 | F4: 82 | G4: 69 | H4: 19 | I4: 2 | J4: 0 | K4: 111 | O4: =($S$1*C3+(1-$S$1)*O3) -> 22.3 | P4: =($S$2*C3+(1-$S$2)*P3) -> 28.9 | Q4: =($S$3*C3+(1-$S$3)*Q3) -> 35.5 | V4: =ABS(C4-O4) -> 21.3 | W4: =ABS(C4-P4) -> 27.9 | X4: =ABS(C4-Q4) -> 34.5
A5: 40175 | B5: 0 | C5: 0 | D5: 0 | E5: 0 | F5: 0 | G5: 0 | H5: 0 | I5: 0 | J5: 0 | K5: 0 | L5: =AVERAGE(C2:C4) -> 24 | M5: =(C5-L5) -> -24 | N5: =ABS(M5) -> 24 | O5: =($S$1*C4+(1-$S$1)*O4) -> 20.17 | P5: =($S$2*C4+(1-$S$2)*P4) -> 20.53 | Q5: =($S$3*C4+(1-$S$3)*Q4) -> 18.25 | V5: =ABS(C5-O5) -> 20.17 | W5: =ABS(C5-P5) -> 20.53 | X5: =ABS(C5-Q5) -> 18.25
A6: 40182 | B6: 0 | C6: 47 | D6: 1152 | E6: 47 | F6: 168 | G6: 0 | H6: 17 | I6: 21 | J6: 0 | K6: 324 | L6: =AVERAGE(C3:C5) -> 17.666667 | M6: =(C6-L6) -> 29.333333 | N6: =ABS(M6) -> 29.333333 | O6: =($S$1*C5+(1-$S$1)*O5) -> 18.153 | P6: =($S$2*C5+(1-$S$2)*P5) -> 14.371 | Q6: =($S$3*C5+(1-$S$3)*Q5) -> 9.125 | V6: =ABS(C6-O6) -> 28.847 | W6: =ABS(C6-P6) -> 32.629 | X6: =ABS(C6-Q6) -> 37.875
A7: 40189 | B7: 0 | C7: 64 | D7: 928 | E7: 64 | F7: 233 | G7: 20 | H7: 23 | I7: 72 | J7: 0 | K7: 190 | L7: =AVERAGE(C4:C6) -> 16 | M7: =(C7-L7) -> 48 | N7: =ABS(M7) -> 48 | O7: =($S$1*C6+(1-$S$1)*O6) -> 21.0377 | P7: =($S$2*C6+(1-$S$2)*P6) -> 24.1597 | Q7: =($S$3*C6+(1-$S$3)*Q6) -> 28.0625 | V7: =ABS(C7-O7) -> 42.9623 | W7: =ABS(C7-P7) -> 39.8403 | X7: =ABS(C7-Q7) -> 35.9375
A8: 40196 | B8: 0 | C8: 49 | D8: 627 | E8: 49 | F8: 897 | G8: 3 | H8: 0 | I8: 23 | J8: 0 | K8: 479 | L8: =AVERAGE(C5:C7) -> 37 | M8: =(C8-L8) -> 12 | N8: =ABS(M8) -> 12 | O8: =($S$1*C7+(1-$S$1)*O7) -> 25.33393 | P8: =($S$2*C7+(1-$S$2)*P7) -> 36.11179 | Q8: =($S$3*C7+(1-$S$3)*Q7) -> 46.03125 | V8: =ABS(C8-O8) -> 23.66607 | W8: =ABS(C8-P8) -> 12.88821 | X8: =ABS(C8-Q8) -> 2.96875
A9: 40203 | B9: 0 | C9: 186 | D9: 864 | E9: 186 | F9: 211 | G9: 0 | H9: 0 | I9: 621 | J9: 114 | K9: 504 | L9: =AVERAGE(C6:C8) -> 53.333333 | M9: =(C9-L9) -> 132.66667 | N9: =ABS(M9) -> 132.66667 | O9: =($S$1*C8+(1-$S$1)*O8) -> 27.700537 | P9: =($S$2*C8+(1-$S$2)*P8) -> 39.978253 | Q9: =($S$3*C8+(1-$S$3)*Q8) -> 47.515625 | V9: =ABS(C9-O9) -> 158.29946 | W9: =ABS(C9-P9) -> 146.02175 | X9: =ABS(C9-Q9) -> 138.48438
A10: 40210 | B10: 0 | C10: 53 | D10: 488 | E10: 53 | F10: 274 | G10: 0 | H10: 24 | I10: 81 | J10: 338 | K10: 326 | L10: =AVERAGE(C7:C9) -> 99.666667 | M10: =(C10-L10) -> -46.666667 | N10: =ABS(M10) -> 46.666667 | O10: =($S$1*C9+(1-$S$1)*O9) -> 43.530483 | P10: =($S$2*C9+(1-$S$2)*P9) -> 83.784777 | Q10: =($S$3*C9+(1-$S$3)*Q9) -> 116.75781 | V10: =ABS(C10-O10) -> 9.4695167 | W10: =ABS(C10-P10) -> 30.784777 | X10: =ABS(C10-Q10) -> 63.757812
A11: 40217 | B11: 0 | C11: 51 | D11: 547 | E11: 51 | F11: 512 | G11: 0 | H11: 0 | I11: 68 | J11: 314 | K11: 213 | L11: =AVERAGE(C8:C10) -> 96 | M11: =(C11-L11) -> -45 | N11: =ABS(M11) -> 45 | O11: =($S$1*C10+(1-$S$1)*O10) -> 44.477435 | P11: =($S$2*C10+(1-$S$2)*P10) -> 74.549344 | Q11: =($S$3*C10+(1-$S$3)*Q10) -> 84.878906 | V11: =ABS(C11-O11) -> 6.522565 | W11: =ABS(C11-P11) -> 23.549344 | X11: =ABS(C11-Q11) -> 33.878906
A12: 40224 | B12: 0 | C12: 159 | D12: 1014 | E12: 159 | F12: 587 | G12: 0 | H12: 1 | I12: 19 | J12: 720 | K12: 442 | L12: =AVERAGE(C9:C11) -> 96.666667 | M12: =(C12-L12) -> 62.333333 | N12: =ABS(M12) -> 62.333333 | O12: =($S$1*C11+(1-$S$1)*O11) -> 45.129691 | P12: =($S$2*C11+(1-$S$2)*P11) -> 67.484541 | Q12: =($S$3*C11+(1-$S$3)*Q11) -> 67.939453 | V12: =ABS(C12-O12) -> 113.87031 | W12: =ABS(C12-P12) -> 91.515459 | X12: =ABS(C12-Q12) -> 91.060547
A13: 40231 | B13: 0 | C13: 79 | D13: 613 | E13: 79 | F13: 294 | G13: 0 | H13: 0 | I13: 1407 | J13: 551 | K13: 272 | L13: =AVERAGE(C10:C12) -> 87.666667 | M13: =(C13-L13) -> -8.6666667 | N13: =ABS(M13) -> 8.6666667 | O13: =($S$1*C12+(1-$S$1)*O12) -> 56.516722 | P13: =($S$2*C12+(1-$S$2)*P12) -> 94.939179 | Q13: =($S$3*C12+(1-$S$3)*Q12) -> 113.46973 | V13: =ABS(C13-O13) -> 22.483278 | W13: =ABS(C13-P13) -> 15.939179 | X13: =ABS(C13-Q13) -> 34.469727
A14: 40238 | B14: 0 | C14: 78 | D14: 754 | E14: 78 | F14: 735 | G14: 3 | H14: 2 | I14: 133 | J14: 306 | K14: 409 | L14: =AVERAGE(C11:C13) -> 96.333333 | M14: =(C14-L14) -> -18.333333 | N14: =ABS(M14) -> 18.333333 | O14: =($S$1*C13+(1-$S$1)*O13) -> 58.76505 | P14: =($S$2*C13+(1-$S$2)*P13) -> 90.157425 | Q14: =($S$3*C13+(1-$S$3)*Q13) -> 96.234863 | V14: =ABS(C14-O14) -> 19.23495 | W14: =ABS(C14-P14) -> 12.157425 | X14: =ABS(C14-Q14) -> 18.234863
A15: 40245 | B15: 0 | C15: 262 | D15: 800 | E15: 262 | F15: 917 | G15: 0 | H15: 0 | I15: 47 | J15: 405 | K15: 337 | L15: =AVERAGE(C12:C14) -> 105.33333 | M15: =(C15-L15) -> 156.66667 | N15: =ABS(M15) -> 156.66667 | O15: =($S$1*C14+(1-$S$1)*O14) -> 60.688545 | P15: =($S$2*C14+(1-$S$2)*P14) -> 86.510197 | Q15: =($S$3*C14+(1-$S$3)*Q14) -> 87.117432 | V15: =ABS(C15-O15) -> 201.31145 | W15: =ABS(C15-P15) -> 175.4898 | X15: =ABS(C15-Q15) -> 174.88257
A16: 40252 | B16: 194 | C16: 224 | D16: 555 | E16: 224 | F16: 551 | G16: 12 | H16: 0 | I16: 826 | J16: 179 | K16: 375 | L16: =AVERAGE(C13:C15) -> 139.66667 | M16: =(C16-L16) -> 84.333333 | N16: =ABS(M16) -> 84.333333 | O16: =($S$1*C15+(1-$S$1)*O15) -> 80.819691 | P16: =($S$2*C15+(1-$S$2)*P15) -> 139.15714 | Q16: =($S$3*C15+(1-$S$3)*Q15) -> 174.55872 | V16: =ABS(C16-O16) -> 143.18031 | W16: =ABS(C16-P16) -> 84.842862 | X16: =ABS(C16-Q16) -> 49.441284
... A105: 40875 | B105: 226 | C105: 105 | D105: 1040 | E105: 105 | F105: 953 | G105: 1564 | H105: 314 | I105: 3275 | J105: 436 | K105: 331 | L105: =AVERAGE(C102:C104) -> 269.33333 | M105: =(C105-L105) -> -164.33333 | N105: =ABS(M105) -> 164.33333 | O105: =($S$1*C104+(1-$S$1)*O104) -> 283.82238 | P105: =($S$2*C104+(1-$S$2)*P104) -> 252.5748 | Q105: =($S$3*C104+(1-$S$3)*Q104) -> 313.40462 | V105: =ABS(C105-O105) -> 178.82238 | W105: =ABS(C105-P105) -> 147.5748 | X105: =ABS(C105-Q105) -> 208.40462
T106: MAD _M3 | U106: =AVERAGE(N94:N105) -> 88.527778
T107: MAD _ES_0.1 | U107: =AVERAGE(V94:V105) -> 186.1182
T108: MAD _ES_0.3 | U108: =AVERAGE(W94:W105) -> 103.76876
T109: MAD _ES_0.5 | U109: =AVERAGE(X94:X105) -> 95.872906
V111: AVERAGE | W111: STD DEV
V112: =AVERAGE(C2:C105) -> 268.28846 | W112: =STDEV(C2:C105) -> 240.7891

Sheet BIRD ORNAMENT
A1: Week_start | B1: 22423 REGENCY CAKESTAND 3 TI | C1: 85123A WHITE HANGING HEART T- | D1: 85099B JUMBO BAG RED RETROSPO | E1: 47566 PARTY BUNTING | F1: 84879 ASSORTED COLOUR BIRD O | G1: 22086 PAPER CHAIN KIT 50'S C | H1: 79321 CHILLI LIGHTS | I1: 22197 SMALL POPCORN HOLDER | J1: 22386 JUMBO BAG PINK POLKADO | K1: 20725 LUNCH BAG RED RETROSPO | L1: MA3_FORECAST | M1: ERROR | N1: ABS ERROR | O1: ES_0.1 | P1: ES_0.3 | Q1: ES_0.5 | R1: ALPHA | S1: 0.1 | V1: ABSERR_0.1 | W1: ABSERR_0.3 | X1: ABSERR_0.5
A2: 40154 | B2: 0 | C2: 1213 | D2: 1233 | E2: 19 | F2: 1213 | G2: 663 | H2: 175 | I2: 153 | J2: 0 | K2: 324 | O2: =(C2) -> 1213 | P2: =(C2) -> 1213 | Q2: =(C2) -> 1213 | S2: 0.3
A3: 40161 | B3: 0 | C3: 1324 | D3: 1304 | E3: 52 | F3: 1324 | G3: 572 | H3: 173 | I3: 644 | J3: 0 | K3: 236 | O3: =($S$1*C2+(1-$S$1)*O2) -> 1213 | P3: =($S$2*C2+(1-$S$2)*P2) -> 1213 | Q3: =($S$3*C2+(1-$S$3)*Q2) -> 1213 | S3: 0.5 | V3: =ABS(C3-O3) -> 111 | W3: =ABS(C3-P3) -> 111 | X3: =ABS(C3-Q3) -> 111
A4: 40168 | B4: 0 | C4: 82 | D4: 36 | E4: 1 | F4: 82 | G4: 69 | H4: 19 | I4: 2 | J4: 0 | K4: 111 | O4: =($S$1*C3+(1-$S$1)*O3) -> 1224.1 | P4: =($S$2*C3+(1-$S$2)*P3) -> 1246.3 | Q4: =($S$3*C3+(1-$S$3)*Q3) -> 1268.5 | V4: =ABS(C4-O4) -> 1142.1 | W4: =ABS(C4-P4) -> 1164.3 | X4: =ABS(C4-Q4) -> 1186.5
A5: 40175 | B5: 0 | C5: 0 | D5: 0 | E5: 0 | F5: 0 | G5: 0 | H5: 0 | I5: 0 | J5: 0 | K5: 0 | L5: =AVERAGE(C2:C4) -> 873 | M5: =(C5-L5) -> -873 | N5: =ABS(M5) -> 873 | O5: =($S$1*C4+(1-$S$1)*O4) -> 1109.89 | P5: =($S$2*C4+(1-$S$2)*P4) -> 897.01 | Q5: =($S$3*C4+(1-$S$3)*Q4) -> 675.25 | V5: =ABS(C5-O5) -> 1109.89 | W5: =ABS(C5-P5) -> 897.01 | X5: =ABS(C5-Q5) -> 675.25
A6: 40182 | B6: 0 | C6: 168 | D6: 1152 | E6: 47 | F6: 168 | G6: 0 | H6: 17 | I6: 21 | J6: 0 | K6: 324 | L6: =AVERAGE(C3:C5) -> 468.66667 | M6: =(C6-L6) -> -300.66667 | N6: =ABS(M6) -> 300.66667 | O6: =($S$1*C5+(1-$S$1)*O5) -> 998.901 | P6: =($S$2*C5+(1-$S$2)*P5) -> 627.907 | Q6: =($S$3*C5+(1-$S$3)*Q5) -> 337.625 | V6: =ABS(C6-O6) -> 830.901 | W6: =ABS(C6-P6) -> 459.907 | X6: =ABS(C6-Q6) -> 169.625
A7: 40189 | B7: 0 | C7: 233 | D7: 928 | E7: 64 | F7: 233 | G7: 20 | H7: 23 | I7: 72 | J7: 0 | K7: 190 | L7: =AVERAGE(C4:C6) -> 83.333333 | M7: =(C7-L7) -> 149.66667 | N7: =ABS(M7) -> 149.66667 | O7: =($S$1*C6+(1-$S$1)*O6) -> 915.8109 | P7: =($S$2*C6+(1-$S$2)*P6) -> 489.9349 | Q7: =($S$3*C6+(1-$S$3)*Q6) -> 252.8125 | V7: =ABS(C7-O7) -> 682.8109 | W7: =ABS(C7-P7) -> 256.9349 | X7: =ABS(C7-Q7) -> 19.8125
A8: 40196 | B8: 0 | C8: 897 | D8: 627 | E8: 49 | F8: 897 | G8: 3 | H8: 0 | I8: 23 | J8: 0 | K8: 479 | L8: =AVERAGE(C5:C7) -> 133.66667 | M8: =(C8-L8) -> 763.33333 | N8: =ABS(M8) -> 763.33333 | O8: =($S$1*C7+(1-$S$1)*O7) -> 847.52981 | P8: =($S$2*C7+(1-$S$2)*P7) -> 412.85443 | Q8: =($S$3*C7+(1-$S$3)*Q7) -> 242.90625 | V8: =ABS(C8-O8) -> 49.47019 | W8: =ABS(C8-P8) -> 484.14557 | X8: =ABS(C8-Q8) -> 654.09375
A9: 40203 | B9: 0 | C9: 211 | D9: 864 | E9: 186 | F9: 211 | G9: 0 | H9: 0 | I9: 621 | J9: 114 | K9: 504 | L9: =AVERAGE(C6:C8) -> 432.66667 | M9: =(C9-L9) -> -221.66667 | N9: =ABS(M9) -> 221.66667 | O9: =($S$1*C8+(1-$S$1)*O8) -> 852.47683 | P9: =($S$2*C8+(1-$S$2)*P8) -> 558.0981 | Q9: =($S$3*C8+(1-$S$3)*Q8) -> 569.95312 | V9: =ABS(C9-O9) -> 641.47683 | W9: =ABS(C9-P9) -> 347.0981 | X9: =ABS(C9-Q9) -> 358.95312
A10: 40210 | B10: 0 | C10: 274 | D10: 488 | E10: 53 | F10: 274 | G10: 0 | H10: 24 | I10: 81 | J10: 338 | K10: 326 | L10: =AVERAGE(C7:C9) -> 447 | M10: =(C10-L10) -> -173 | N10: =ABS(M10) -> 173 | O10: =($S$1*C9+(1-$S$1)*O9) -> 788.32915 | P10: =($S$2*C9+(1-$S$2)*P9) -> 453.96867 | Q10: =($S$3*C9+(1-$S$3)*Q9) -> 390.47656 | V10: =ABS(C10-O10) -> 514.32915 | W10: =ABS(C10-P10) -> 179.96867 | X10: =ABS(C10-Q10) -> 116.47656
